2023-09-22 00:08:46 : Command '버튼' raised an exception: HTTPException: 400 Bad Request (error code: 50035): Invalid Form Body
In data.components.0.components.0.emoji.id: Invalid emoji
Traceback (most recent call last):
  File "C:\Users\ghftr\AppData\Roaming\Python\Python311\site-packages\discord\app_commands\commands.py", line 861, in _do_call
    return await self._callback(self.binding, interaction, **params)  # type: ignore
           ^^^^^^^^^^^^^^^^^^^^^^^^^^^^^^^^^^^^^^^^^^^^^^^^^^^^^^^^^
  File "C:\Users\ghftr\Documents\GitHub\arislena-reborn\arislena-reborn\cogs\test.py", line 18, in test
    await interaction.response.send_message("버튼을 눌러봐!", view=button_interaction.test_button())
  File "C:\Users\ghftr\AppData\Roaming\Python\Python311\site-packages\discord\interactions.py", line 769, in send_message
    await adapter.create_interaction_response(
  File "C:\Users\ghftr\AppData\Roaming\Python\Python311\site-packages\discord\webhook\async_.py", line 220, in request
    raise HTTPException(response, data)
discord.errors.HTTPException: 400 Bad Request (error code: 50035): Invalid Form Body
In data.components.0.components.0.emoji.id: Invalid emoji

The above exception was the direct cause of the following exception:

Traceback (most recent call last):
  File "C:\Users\ghftr\AppData\Roaming\Python\Python311\site-packages\discord\app_commands\tree.py", line 1242, in _call
    await command._invoke_with_namespace(interaction, namespace)
  File "C:\Users\ghftr\AppData\Roaming\Python\Python311\site-packages\discord\app_commands\commands.py", line 887, in _invoke_with_namespace
    return await self._do_call(interaction, transformed_values)
           ^^^^^^^^^^^^^^^^^^^^^^^^^^^^^^^^^^^^^^^^^^^^^^^^^^^^
  File "C:\Users\ghftr\AppData\Roaming\Python\Python311\site-packages\discord\app_commands\commands.py", line 880, in _do_call
    raise CommandInvokeError(self, e) from e
discord.app_commands.errors.CommandInvokeError: Command '버튼' raised an exception: HTTPException: 400 Bad Request (error code: 50035): Invalid Form Body
In data.components.0.components.0.emoji.id: Invalid emoji

2023-09-22 17:19:21 : Command '등록신청' raised an exception: AttributeError: module 'py.database' has no attribute 'User'
Traceback (most recent call last):
  File "C:\Users\ghftr\AppData\Roaming\Python\Python311\site-packages\discord\app_commands\commands.py", line 861, in _do_call
    return await self._callback(self.binding, interaction, **params)  # type: ignore
           ^^^^^^^^^^^^^^^^^^^^^^^^^^^^^^^^^^^^^^^^^^^^^^^^^^^^^^^^^
  File "C:\Users\ghftr\Documents\GitHub\arislena-reborn\arislena-reborn\cogs\user_management.py", line 27, in register
    user:tableobj.User = db.fetch("user", f"discord_id = {interaction.user.id}")
                         ^^^^^^^^^^^^^^^^^^^^^^^^^^^^^^^^^^^^^^^^^^^^^^^^^^^^^^^
  File "C:\Users\ghftr\Documents\GitHub\arislena-reborn\arislena-reborn\py\database.py", line 40, in fetch
    return getattr(sys.modules[__name__], table.capitalize())(*data)
           ^^^^^^^^^^^^^^^^^^^^^^^^^^^^^^^^^^^^^^^^^^^^^^^^^^
AttributeError: module 'py.database' has no attribute 'User'

The above exception was the direct cause of the following exception:

Traceback (most recent call last):
  File "C:\Users\ghftr\AppData\Roaming\Python\Python311\site-packages\discord\app_commands\tree.py", line 1242, in _call
    await command._invoke_with_namespace(interaction, namespace)
  File "C:\Users\ghftr\AppData\Roaming\Python\Python311\site-packages\discord\app_commands\commands.py", line 887, in _invoke_with_namespace
    return await self._do_call(interaction, transformed_values)
           ^^^^^^^^^^^^^^^^^^^^^^^^^^^^^^^^^^^^^^^^^^^^^^^^^^^^
  File "C:\Users\ghftr\AppData\Roaming\Python\Python311\site-packages\discord\app_commands\commands.py", line 880, in _do_call
    raise CommandInvokeError(self, e) from e
discord.app_commands.errors.CommandInvokeError: Command '등록신청' raised an exception: AttributeError: module 'py.database' has no attribute 'User'

2023-09-22 18:01:31 : Command '등록' raised an exception: TypeError: Expected discord.Colour, int, or None but received Color instead.
Traceback (most recent call last):
  File "C:\Users\ghftr\AppData\Roaming\Python\Python311\site-packages\discord\app_commands\commands.py", line 861, in _do_call
    return await self._callback(self.binding, interaction, **params)  # type: ignore
           ^^^^^^^^^^^^^^^^^^^^^^^^^^^^^^^^^^^^^^^^^^^^^^^^^^^^^^^^^
  File "C:\Users\ghftr\Documents\GitHub\arislena-reborn\arislena-reborn\cogs\user_management.py", line 37, in register
    embed = discord.Embed(title=embed_title, description=embed_description, color=embed_color)
            ^^^^^^^^^^^^^^^^^^^^^^^^^^^^^^^^^^^^^^^^^^^^^^^^^^^^^^^^^^^^^^^^^^^^^^^^^^^^^^^^^^
  File "C:\Users\ghftr\AppData\Roaming\Python\Python311\site-packages\discord\embeds.py", line 179, in __init__
    self.colour = colour if colour is not None else color
    ^^^^^^^^^^^
  File "C:\Users\ghftr\AppData\Roaming\Python\Python311\site-packages\discord\embeds.py", line 323, in colour
    raise TypeError(f'Expected discord.Colour, int, or None but received {value.__class__.__name__} instead.')
TypeError: Expected discord.Colour, int, or None but received Color instead.

The above exception was the direct cause of the following exception:

Traceback (most recent call last):
  File "C:\Users\ghftr\AppData\Roaming\Python\Python311\site-packages\discord\app_commands\tree.py", line 1242, in _call
    await command._invoke_with_namespace(interaction, namespace)
  File "C:\Users\ghftr\AppData\Roaming\Python\Python311\site-packages\discord\app_commands\commands.py", line 887, in _invoke_with_namespace
    return await self._do_call(interaction, transformed_values)
           ^^^^^^^^^^^^^^^^^^^^^^^^^^^^^^^^^^^^^^^^^^^^^^^^^^^^
  File "C:\Users\ghftr\AppData\Roaming\Python\Python311\site-packages\discord\app_commands\commands.py", line 876, in _do_call
    raise CommandInvokeError(self, e) from e
discord.app_commands.errors.CommandInvokeError: Command '등록' raised an exception: TypeError: Expected discord.Colour, int, or None but received Color instead.

2023-09-25 17:54:56 : Command '등록' raised an exception: OperationalError: no such column: None
Traceback (most recent call last):
  File "C:\Users\ghftr\AppData\Roaming\Python\Python311\site-packages\discord\app_commands\commands.py", line 861, in _do_call
    return await self._callback(self.binding, interaction, **params)  # type: ignore
           ^^^^^^^^^^^^^^^^^^^^^^^^^^^^^^^^^^^^^^^^^^^^^^^^^^^^^^^^^
  File "C:\Users\ghftr\Documents\GitHub\arislena-reborn\arislena-reborn\cogs\user_management.py", line 33, in register
    db.insert(user)
  File "C:\Users\ghftr\Documents\GitHub\arislena-reborn\arislena-reborn\py\database.py", line 142, in insert
    self.cursor.execute(sql)
sqlite3.OperationalError: no such column: None

The above exception was the direct cause of the following exception:

Traceback (most recent call last):
  File "C:\Users\ghftr\AppData\Roaming\Python\Python311\site-packages\discord\app_commands\tree.py", line 1242, in _call
    await command._invoke_with_namespace(interaction, namespace)
  File "C:\Users\ghftr\AppData\Roaming\Python\Python311\site-packages\discord\app_commands\commands.py", line 887, in _invoke_with_namespace
    return await self._do_call(interaction, transformed_values)
           ^^^^^^^^^^^^^^^^^^^^^^^^^^^^^^^^^^^^^^^^^^^^^^^^^^^^
  File "C:\Users\ghftr\AppData\Roaming\Python\Python311\site-packages\discord\app_commands\commands.py", line 880, in _do_call
    raise CommandInvokeError(self, e) from e
discord.app_commands.errors.CommandInvokeError: Command '등록' raised an exception: OperationalError: no such column: None

2023-10-15 21:12:38 : Command '목록' raised an exception: AttributeError: type object 'DiceMemory' has no attribute 'content'
Traceback (most recent call last):
  File "C:\Users\ghftr\AppData\Roaming\Python\Python311\site-packages\discord\app_commands\commands.py", line 861, in _do_call
    return await self._callback(self.binding, interaction, **params)  # type: ignore
           ^^^^^^^^^^^^^^^^^^^^^^^^^^^^^^^^^^^^^^^^^^^^^^^^^^^^^^^^^
  File "C:\Users\ghftr\Documents\GitHub\arislena-reborn\arislena-reborn\cogs\dice_package.py", line 112, in show_dice_list
    registered_dice_list = jsonobj.DiceMemory.content
                           ^^^^^^^^^^^^^^^^^^^^^^^^^^
AttributeError: type object 'DiceMemory' has no attribute 'content'

The above exception was the direct cause of the following exception:

Traceback (most recent call last):
  File "C:\Users\ghftr\AppData\Roaming\Python\Python311\site-packages\discord\app_commands\tree.py", line 1242, in _call
    await command._invoke_with_namespace(interaction, namespace)
  File "C:\Users\ghftr\AppData\Roaming\Python\Python311\site-packages\discord\app_commands\commands.py", line 887, in _invoke_with_namespace
    return await self._do_call(interaction, transformed_values)
           ^^^^^^^^^^^^^^^^^^^^^^^^^^^^^^^^^^^^^^^^^^^^^^^^^^^^
  File "C:\Users\ghftr\AppData\Roaming\Python\Python311\site-packages\discord\app_commands\commands.py", line 880, in _do_call
    raise CommandInvokeError(self, e) from e
discord.app_commands.errors.CommandInvokeError: Command '목록' raised an exception: AttributeError: type object 'DiceMemory' has no attribute 'content'

2023-10-22 22:24:12 : Command '등록' raised an exception: OperationalError: no such column: None
Traceback (most recent call last):
  File "C:\Users\정진혁\AppData\Roaming\Python\Python311\site-packages\discord\app_commands\commands.py", line 827, in _do_call
    return await self._callback(self.binding, interaction, **params)  # type: ignore
           ^^^^^^^^^^^^^^^^^^^^^^^^^^^^^^^^^^^^^^^^^^^^^^^^^^^^^^^^^
  File "C:\Users\정진혁\OneDrive - Ars Praxia\Documents\GitHub\arislena-reborn\cogs\user_management.py", line 33, in register
    main_db.insert(tableobj.User_setting(user_ID=user.ID))
  File "C:\Users\정진혁\OneDrive - Ars Praxia\Documents\GitHub\arislena-reborn\py_system\database.py", line 144, in insert
    self.cursor.execute(sql)
sqlite3.OperationalError: no such column: None

The above exception was the direct cause of the following exception:

Traceback (most recent call last):
  File "C:\Users\정진혁\AppData\Roaming\Python\Python311\site-packages\discord\app_commands\tree.py", line 1248, in _call
    await command._invoke_with_namespace(interaction, namespace)
  File "C:\Users\정진혁\AppData\Roaming\Python\Python311\site-packages\discord\app_commands\commands.py", line 853, in _invoke_with_namespace
    return await self._do_call(interaction, transformed_values)
           ^^^^^^^^^^^^^^^^^^^^^^^^^^^^^^^^^^^^^^^^^^^^^^^^^^^^
  File "C:\Users\정진혁\AppData\Roaming\Python\Python311\site-packages\discord\app_commands\commands.py", line 846, in _do_call
    raise CommandInvokeError(self, e) from e
discord.app_commands.errors.CommandInvokeError: Command '등록' raised an exception: OperationalError: no such column: None

2023-10-22 22:26:06 : Command '등록' raised an exception: OperationalError: no such column: None
Traceback (most recent call last):
  File "C:\Users\정진혁\AppData\Roaming\Python\Python311\site-packages\discord\app_commands\commands.py", line 827, in _do_call
    return await self._callback(self.binding, interaction, **params)  # type: ignore
           ^^^^^^^^^^^^^^^^^^^^^^^^^^^^^^^^^^^^^^^^^^^^^^^^^^^^^^^^^
  File "C:\Users\정진혁\OneDrive - Ars Praxia\Documents\GitHub\arislena-reborn\cogs\user_management.py", line 33, in register
    main_db.insert(tableobj.User_setting(user_ID=user.ID))
  File "C:\Users\정진혁\OneDrive - Ars Praxia\Documents\GitHub\arislena-reborn\py_system\database.py", line 144, in insert
    self.cursor.execute(sql)
sqlite3.OperationalError: no such column: None

The above exception was the direct cause of the following exception:

Traceback (most recent call last):
  File "C:\Users\정진혁\AppData\Roaming\Python\Python311\site-packages\discord\app_commands\tree.py", line 1248, in _call
    await command._invoke_with_namespace(interaction, namespace)
  File "C:\Users\정진혁\AppData\Roaming\Python\Python311\site-packages\discord\app_commands\commands.py", line 853, in _invoke_with_namespace
    return await self._do_call(interaction, transformed_values)
           ^^^^^^^^^^^^^^^^^^^^^^^^^^^^^^^^^^^^^^^^^^^^^^^^^^^^
  File "C:\Users\정진혁\AppData\Roaming\Python\Python311\site-packages\discord\app_commands\commands.py", line 846, in _do_call
    raise CommandInvokeError(self, e) from e
discord.app_commands.errors.CommandInvokeError: Command '등록' raised an exception: OperationalError: no such column: None

2023-10-22 22:33:29 : Command '등록' raised an exception: TypeError: User_setting.__init__() got an unexpected keyword argument 'user_ID'
Traceback (most recent call last):
  File "C:\Users\정진혁\AppData\Roaming\Python\Python311\site-packages\discord\app_commands\commands.py", line 827, in _do_call
    return await self._callback(self.binding, interaction, **params)  # type: ignore
           ^^^^^^^^^^^^^^^^^^^^^^^^^^^^^^^^^^^^^^^^^^^^^^^^^^^^^^^^^
  File "C:\Users\정진혁\OneDrive - Ars Praxia\Documents\GitHub\arislena-reborn\cogs\user_management.py", line 32, in register
    user_settings = tableobj.User_setting(user_ID=interaction.user.id)
                    ^^^^^^^^^^^^^^^^^^^^^^^^^^^^^^^^^^^^^^^^^^^^^^^^^^
TypeError: User_setting.__init__() got an unexpected keyword argument 'user_ID'

The above exception was the direct cause of the following exception:

Traceback (most recent call last):
  File "C:\Users\정진혁\AppData\Roaming\Python\Python311\site-packages\discord\app_commands\tree.py", line 1248, in _call
    await command._invoke_with_namespace(interaction, namespace)
  File "C:\Users\정진혁\AppData\Roaming\Python\Python311\site-packages\discord\app_commands\commands.py", line 853, in _invoke_with_namespace
    return await self._do_call(interaction, transformed_values)
           ^^^^^^^^^^^^^^^^^^^^^^^^^^^^^^^^^^^^^^^^^^^^^^^^^^^^
  File "C:\Users\정진혁\AppData\Roaming\Python\Python311\site-packages\discord\app_commands\commands.py", line 842, in _do_call
    raise CommandInvokeError(self, e) from e
discord.app_commands.errors.CommandInvokeError: Command '등록' raised an exception: TypeError: User_setting.__init__() got an unexpected keyword argument 'user_ID'

2023-10-22 22:47:40 : Command '설정' raised an exception: TypeError: convert_to_tableobj() takes 2 positional arguments but 5 were given
Traceback (most recent call last):
  File "C:\Users\정진혁\AppData\Roaming\Python\Python311\site-packages\discord\app_commands\commands.py", line 827, in _do_call
    return await self._callback(self.binding, interaction, **params)  # type: ignore
           ^^^^^^^^^^^^^^^^^^^^^^^^^^^^^^^^^^^^^^^^^^^^^^^^^^^^^^^^^
  File "C:\Users\정진혁\OneDrive - Ars Praxia\Documents\GitHub\arislena-reborn\cogs\user_management.py", line 59, in setting
    user:tableobj.User = main_db.fetch("user", f"discord_id = {interaction.user.id}")
                         ^^^^^^^^^^^^^^^^^^^^^^^^^^^^^^^^^^^^^^^^^^^^^^^^^^^^^^^^^^^^
  File "C:\Users\정진혁\OneDrive - Ars Praxia\Documents\GitHub\arislena-reborn\py_system\database.py", line 41, in fetch
    return tableobj.convert_to_tableobj(table, *data)
           ^^^^^^^^^^^^^^^^^^^^^^^^^^^^^^^^^^^^^^^^^^
TypeError: convert_to_tableobj() takes 2 positional arguments but 5 were given

The above exception was the direct cause of the following exception:

Traceback (most recent call last):
  File "C:\Users\정진혁\AppData\Roaming\Python\Python311\site-packages\discord\app_commands\tree.py", line 1248, in _call
    await command._invoke_with_namespace(interaction, namespace)
  File "C:\Users\정진혁\AppData\Roaming\Python\Python311\site-packages\discord\app_commands\commands.py", line 853, in _invoke_with_namespace
    return await self._do_call(interaction, transformed_values)
           ^^^^^^^^^^^^^^^^^^^^^^^^^^^^^^^^^^^^^^^^^^^^^^^^^^^^
  File "C:\Users\정진혁\AppData\Roaming\Python\Python311\site-packages\discord\app_commands\commands.py", line 842, in _do_call
    raise CommandInvokeError(self, e) from e
discord.app_commands.errors.CommandInvokeError: Command '설정' raised an exception: TypeError: convert_to_tableobj() takes 2 positional arguments but 5 were given

2023-10-22 22:49:38 : Command '설정' raised an exception: OperationalError: no such column: user_ID
Traceback (most recent call last):
  File "C:\Users\정진혁\AppData\Roaming\Python\Python311\site-packages\discord\app_commands\commands.py", line 827, in _do_call
    return await self._callback(self.binding, interaction, **params)  # type: ignore
           ^^^^^^^^^^^^^^^^^^^^^^^^^^^^^^^^^^^^^^^^^^^^^^^^^^^^^^^^^
  File "C:\Users\정진혁\OneDrive - Ars Praxia\Documents\GitHub\arislena-reborn\cogs\user_management.py", line 63, in setting
    user_setting = main_db.fetch("user_setting", f"user_ID = {user.ID}")
                   ^^^^^^^^^^^^^^^^^^^^^^^^^^^^^^^^^^^^^^^^^^^^^^^^^^^^^
  File "C:\Users\정진혁\OneDrive - Ars Praxia\Documents\GitHub\arislena-reborn\py_system\database.py", line 35, in fetch
    self.cursor.execute(sql)
sqlite3.OperationalError: no such column: user_ID

The above exception was the direct cause of the following exception:

Traceback (most recent call last):
  File "C:\Users\정진혁\AppData\Roaming\Python\Python311\site-packages\discord\app_commands\tree.py", line 1248, in _call
    await command._invoke_with_namespace(interaction, namespace)
  File "C:\Users\정진혁\AppData\Roaming\Python\Python311\site-packages\discord\app_commands\commands.py", line 853, in _invoke_with_namespace
    return await self._do_call(interaction, transformed_values)
           ^^^^^^^^^^^^^^^^^^^^^^^^^^^^^^^^^^^^^^^^^^^^^^^^^^^^
  File "C:\Users\정진혁\AppData\Roaming\Python\Python311\site-packages\discord\app_commands\commands.py", line 846, in _do_call
    raise CommandInvokeError(self, e) from e
discord.app_commands.errors.CommandInvokeError: Command '설정' raised an exception: OperationalError: no such column: user_ID

2024-01-19 18:57:47 : Command '등록' raised an exception: TypeError: User.__init__() got an unexpected keyword argument 'discord_id'
Traceback (most recent call last):
  File "C:\Users\ghftr\AppData\Roaming\Python\Python311\site-packages\discord\app_commands\commands.py", line 827, in _do_call
    return await self._callback(self.binding, interaction, **params)  # type: ignore
           ^^^^^^^^^^^^^^^^^^^^^^^^^^^^^^^^^^^^^^^^^^^^^^^^^^^^^^^^^
  File "C:\Users\ghftr\Documents\GitHub\arislena-reborn\cogs\user_management.py", line 28, in register
    user = tableobj.User(
           ^^^^^^^^^^^^^^
TypeError: User.__init__() got an unexpected keyword argument 'discord_id'

The above exception was the direct cause of the following exception:

Traceback (most recent call last):
  File "C:\Users\ghftr\AppData\Roaming\Python\Python311\site-packages\discord\app_commands\tree.py", line 1248, in _call
    await command._invoke_with_namespace(interaction, namespace)
  File "C:\Users\ghftr\AppData\Roaming\Python\Python311\site-packages\discord\app_commands\commands.py", line 853, in _invoke_with_namespace
    return await self._do_call(interaction, transformed_values)
           ^^^^^^^^^^^^^^^^^^^^^^^^^^^^^^^^^^^^^^^^^^^^^^^^^^^^
  File "C:\Users\ghftr\AppData\Roaming\Python\Python311\site-packages\discord\app_commands\commands.py", line 842, in _do_call
    raise CommandInvokeError(self, e) from e
discord.app_commands.errors.CommandInvokeError: Command '등록' raised an exception: TypeError: User.__init__() got an unexpected keyword argument 'discord_id'

2024-01-19 19:11:16 : Command '등록' raised an exception: AttributeError: 'User' object has no attribute 'discord_id'
Traceback (most recent call last):
  File "C:\Users\ghftr\AppData\Roaming\Python\Python311\site-packages\discord\app_commands\commands.py", line 827, in _do_call
    return await self._callback(self.binding, interaction, **params)  # type: ignore
           ^^^^^^^^^^^^^^^^^^^^^^^^^^^^^^^^^^^^^^^^^^^^^^^^^^^^^^^^^
  File "C:\Users\ghftr\Documents\GitHub\arislena-reborn\cogs\user_management.py", line 51, in register
    await interaction.response.send_message(embed=embed.register(user), ephemeral=True)
                                                  ^^^^^^^^^^^^^^^^^^^^
  File "C:\Users\ghftr\Documents\GitHub\arislena-reborn\py_discord\embed.py", line 11, in register
    embed.add_field(name="디스코드 아이디", value=user.discord_id)
                                           ^^^^^^^^^^^^^^^
AttributeError: 'User' object has no attribute 'discord_id'

The above exception was the direct cause of the following exception:

Traceback (most recent call last):
  File "C:\Users\ghftr\AppData\Roaming\Python\Python311\site-packages\discord\app_commands\tree.py", line 1248, in _call
    await command._invoke_with_namespace(interaction, namespace)
  File "C:\Users\ghftr\AppData\Roaming\Python\Python311\site-packages\discord\app_commands\commands.py", line 853, in _invoke_with_namespace
    return await self._do_call(interaction, transformed_values)
           ^^^^^^^^^^^^^^^^^^^^^^^^^^^^^^^^^^^^^^^^^^^^^^^^^^^^
  File "C:\Users\ghftr\AppData\Roaming\Python\Python311\site-packages\discord\app_commands\commands.py", line 846, in _do_call
    raise CommandInvokeError(self, e) from e
discord.app_commands.errors.CommandInvokeError: Command '등록' raised an exception: AttributeError: 'User' object has no attribute 'discord_id'

2024-01-20 10:53:38 : Command '모두열람' raised an exception: TypeError: convert_to_tableobj() takes 2 positional arguments but 5 were given
Traceback (most recent call last):
  File "C:\Users\ghftr\AppData\Roaming\Python\Python311\site-packages\discord\app_commands\commands.py", line 827, in _do_call
    return await self._callback(self.binding, interaction, **params)  # type: ignore
           ^^^^^^^^^^^^^^^^^^^^^^^^^^^^^^^^^^^^^^^^^^^^^^^^^^^^^^^^^
  File "C:\Users\ghftr\Documents\GitHub\arislena-reborn\cogs\user_management.py", line 87, in info_all
    users:list[tableobj.User] = main_db.fetch_all("user")
                                ^^^^^^^^^^^^^^^^^^^^^^^^^
  File "C:\Users\ghftr\Documents\GitHub\arislena-reborn\py_system\database.py", line 78, in fetch_all
    return [tableobj.convert_to_tableobj(table, *d) for d in data]
           ^^^^^^^^^^^^^^^^^^^^^^^^^^^^^^^^^^^^^^^^^^^^^^^^^^^^^^^
  File "C:\Users\ghftr\Documents\GitHub\arislena-reborn\py_system\database.py", line 78, in <listcomp>
    return [tableobj.convert_to_tableobj(table, *d) for d in data]
            ^^^^^^^^^^^^^^^^^^^^^^^^^^^^^^^^^^^^^^^
TypeError: convert_to_tableobj() takes 2 positional arguments but 5 were given

The above exception was the direct cause of the following exception:

Traceback (most recent call last):
  File "C:\Users\ghftr\AppData\Roaming\Python\Python311\site-packages\discord\app_commands\tree.py", line 1248, in _call
    await command._invoke_with_namespace(interaction, namespace)
  File "C:\Users\ghftr\AppData\Roaming\Python\Python311\site-packages\discord\app_commands\commands.py", line 853, in _invoke_with_namespace
    return await self._do_call(interaction, transformed_values)
           ^^^^^^^^^^^^^^^^^^^^^^^^^^^^^^^^^^^^^^^^^^^^^^^^^^^^
  File "C:\Users\ghftr\AppData\Roaming\Python\Python311\site-packages\discord\app_commands\commands.py", line 842, in _do_call
    raise CommandInvokeError(self, e) from e
discord.app_commands.errors.CommandInvokeError: Command '모두열람' raised an exception: TypeError: convert_to_tableobj() takes 2 positional arguments but 5 were given

2024-01-20 12:43:52 : Command '바로시행' raised an exception: TypeError: Birth1.__init__() missing 1 required positional argument: 'dice_mod'
Traceback (most recent call last):
  File "C:\Users\ghftr\AppData\Roaming\Python\Python311\site-packages\discord\app_commands\commands.py", line 827, in _do_call
    return await self._callback(self.binding, interaction, **params)  # type: ignore
           ^^^^^^^^^^^^^^^^^^^^^^^^^^^^^^^^^^^^^^^^^^^^^^^^^^^^^^^^^
  File "C:\Users\ghftr\Documents\GitHub\arislena-reborn\cogs\dice_package.py", line 284, in roll_a_dice_without_register
    sub_dice = sub_dice()
               ^^^^^^^^^^
TypeError: Birth1.__init__() missing 1 required positional argument: 'dice_mod'

The above exception was the direct cause of the following exception:

Traceback (most recent call last):
  File "C:\Users\ghftr\AppData\Roaming\Python\Python311\site-packages\discord\app_commands\tree.py", line 1248, in _call
    await command._invoke_with_namespace(interaction, namespace)
  File "C:\Users\ghftr\AppData\Roaming\Python\Python311\site-packages\discord\app_commands\commands.py", line 853, in _invoke_with_namespace
    return await self._do_call(interaction, transformed_values)
           ^^^^^^^^^^^^^^^^^^^^^^^^^^^^^^^^^^^^^^^^^^^^^^^^^^^^
  File "C:\Users\ghftr\AppData\Roaming\Python\Python311\site-packages\discord\app_commands\commands.py", line 842, in _do_call
    raise CommandInvokeError(self, e) from e
discord.app_commands.errors.CommandInvokeError: Command '바로시행' raised an exception: TypeError: Birth1.__init__() missing 1 required positional argument: 'dice_mod'

2024-01-20 12:44:19 : Command '등록' raised an exception: KeyError: 1153637128383770644
Traceback (most recent call last):
  File "C:\Users\ghftr\AppData\Roaming\Python\Python311\site-packages\discord\app_commands\commands.py", line 827, in _do_call
    return await self._callback(self.binding, interaction, **params)  # type: ignore
           ^^^^^^^^^^^^^^^^^^^^^^^^^^^^^^^^^^^^^^^^^^^^^^^^^^^^^^^^^
  File "C:\Users\ghftr\Documents\GitHub\arislena-reborn\cogs\user_management.py", line 43, in register
    channel = self.bot.get_channel(settings.announce_location[interaction.guild.id])
                                   ~~~~~~~~~~~~~~~~~~~~~~~~~~^^^^^^^^^^^^^^^^^^^^^^
KeyError: 1153637128383770644

The above exception was the direct cause of the following exception:

Traceback (most recent call last):
  File "C:\Users\ghftr\AppData\Roaming\Python\Python311\site-packages\discord\app_commands\tree.py", line 1248, in _call
    await command._invoke_with_namespace(interaction, namespace)
  File "C:\Users\ghftr\AppData\Roaming\Python\Python311\site-packages\discord\app_commands\commands.py", line 853, in _invoke_with_namespace
    return await self._do_call(interaction, transformed_values)
           ^^^^^^^^^^^^^^^^^^^^^^^^^^^^^^^^^^^^^^^^^^^^^^^^^^^^
  File "C:\Users\ghftr\AppData\Roaming\Python\Python311\site-packages\discord\app_commands\commands.py", line 846, in _do_call
    raise CommandInvokeError(self, e) from e
discord.app_commands.errors.CommandInvokeError: Command '등록' raised an exception: KeyError: 1153637128383770644

2024-01-21 18:48:56 : Command '창설' raised an exception: OperationalError: no such column: owner_id
Traceback (most recent call last):
  File "C:\Users\ghftr\AppData\Roaming\Python\Python311\site-packages\discord\app_commands\commands.py", line 827, in _do_call
    return await self._callback(self.binding, interaction, **params)  # type: ignore
           ^^^^^^^^^^^^^^^^^^^^^^^^^^^^^^^^^^^^^^^^^^^^^^^^^^^^^^^^^
  File "C:\Users\ghftr\Documents\GitHub\arislena-reborn\cogs\faction.py", line 29, in create
    if main_db.fetch("faction", f"owner_id = {interaction.user.id}"):
       ^^^^^^^^^^^^^^^^^^^^^^^^^^^^^^^^^^^^^^^^^^^^^^^^^^^^^^^^^^^^^
  File "C:\Users\ghftr\Documents\GitHub\arislena-reborn\py_system\database.py", line 35, in fetch
    self.cursor.execute(sql)
sqlite3.OperationalError: no such column: owner_id

The above exception was the direct cause of the following exception:

Traceback (most recent call last):
  File "C:\Users\ghftr\AppData\Roaming\Python\Python311\site-packages\discord\app_commands\tree.py", line 1248, in _call
    await command._invoke_with_namespace(interaction, namespace)
  File "C:\Users\ghftr\AppData\Roaming\Python\Python311\site-packages\discord\app_commands\commands.py", line 853, in _invoke_with_namespace
    return await self._do_call(interaction, transformed_values)
           ^^^^^^^^^^^^^^^^^^^^^^^^^^^^^^^^^^^^^^^^^^^^^^^^^^^^
  File "C:\Users\ghftr\AppData\Roaming\Python\Python311\site-packages\discord\app_commands\commands.py", line 846, in _do_call
    raise CommandInvokeError(self, e) from e
discord.app_commands.errors.CommandInvokeError: Command '창설' raised an exception: OperationalError: no such column: owner_id

2024-01-29 10:52:02 : Command '모달' raised an exception: HTTPException: 400 Bad Request (error code: 50035): Invalid Form Body
In data.components.0.components.0: Value of field "type" must be one of (2, 3, 5, 6, 7, 8).
In data.components.1.components.0: Value of field "type" must be one of (2, 3, 5, 6, 7, 8).
Traceback (most recent call last):
  File "C:\Users\ghftr\AppData\Roaming\Python\Python311\site-packages\discord\app_commands\commands.py", line 827, in _do_call
    return await self._callback(self.binding, interaction, **params)  # type: ignore
           ^^^^^^^^^^^^^^^^^^^^^^^^^^^^^^^^^^^^^^^^^^^^^^^^^^^^^^^^^
  File "c:\Users\ghftr\Documents\GitHub\arislena-reborn\cogs\test.py", line 32, in test3
    await interaction.response.send_message("모달을 열어봐!", view=modals.ModalTest())
  File "C:\Users\ghftr\AppData\Roaming\Python\Python311\site-packages\discord\interactions.py", line 801, in send_message
    await adapter.create_interaction_response(
  File "C:\Users\ghftr\AppData\Roaming\Python\Python311\site-packages\discord\webhook\async_.py", line 221, in request
    raise HTTPException(response, data)
discord.errors.HTTPException: 400 Bad Request (error code: 50035): Invalid Form Body
In data.components.0.components.0: Value of field "type" must be one of (2, 3, 5, 6, 7, 8).
In data.components.1.components.0: Value of field "type" must be one of (2, 3, 5, 6, 7, 8).

The above exception was the direct cause of the following exception:

Traceback (most recent call last):
  File "C:\Users\ghftr\AppData\Roaming\Python\Python311\site-packages\discord\app_commands\tree.py", line 1248, in _call
    await command._invoke_with_namespace(interaction, namespace)
  File "C:\Users\ghftr\AppData\Roaming\Python\Python311\site-packages\discord\app_commands\commands.py", line 853, in _invoke_with_namespace
    return await self._do_call(interaction, transformed_values)
           ^^^^^^^^^^^^^^^^^^^^^^^^^^^^^^^^^^^^^^^^^^^^^^^^^^^^
  File "C:\Users\ghftr\AppData\Roaming\Python\Python311\site-packages\discord\app_commands\commands.py", line 846, in _do_call
    raise CommandInvokeError(self, e) from e
discord.app_commands.errors.CommandInvokeError: Command '모달' raised an exception: HTTPException: 400 Bad Request (error code: 50035): Invalid Form Body
In data.components.0.components.0: Value of field "type" must be one of (2, 3, 5, 6, 7, 8).
In data.components.1.components.0: Value of field "type" must be one of (2, 3, 5, 6, 7, 8).

2024-01-29 10:53:51 : Command '모달' raised an exception: HTTPException: 400 Bad Request (error code: 50035): Invalid Form Body
In data.components.0.components.0: Value of field "type" must be one of (2, 3, 5, 6, 7, 8).
In data.components.1.components.0: Value of field "type" must be one of (2, 3, 5, 6, 7, 8).
Traceback (most recent call last):
  File "C:\Users\ghftr\AppData\Roaming\Python\Python311\site-packages\discord\app_commands\commands.py", line 827, in _do_call
    return await self._callback(self.binding, interaction, **params)  # type: ignore
           ^^^^^^^^^^^^^^^^^^^^^^^^^^^^^^^^^^^^^^^^^^^^^^^^^^^^^^^^^
  File "c:\Users\ghftr\Documents\GitHub\arislena-reborn\cogs\test.py", line 32, in test3
    await interaction.response.send_message("모달을 열어봐!", view=modals.ModalTest())
  File "C:\Users\ghftr\AppData\Roaming\Python\Python311\site-packages\discord\interactions.py", line 801, in send_message
    await adapter.create_interaction_response(
  File "C:\Users\ghftr\AppData\Roaming\Python\Python311\site-packages\discord\webhook\async_.py", line 221, in request
    raise HTTPException(response, data)
discord.errors.HTTPException: 400 Bad Request (error code: 50035): Invalid Form Body
In data.components.0.components.0: Value of field "type" must be one of (2, 3, 5, 6, 7, 8).
In data.components.1.components.0: Value of field "type" must be one of (2, 3, 5, 6, 7, 8).

The above exception was the direct cause of the following exception:

Traceback (most recent call last):
  File "C:\Users\ghftr\AppData\Roaming\Python\Python311\site-packages\discord\app_commands\tree.py", line 1248, in _call
    await command._invoke_with_namespace(interaction, namespace)
  File "C:\Users\ghftr\AppData\Roaming\Python\Python311\site-packages\discord\app_commands\commands.py", line 853, in _invoke_with_namespace
    return await self._do_call(interaction, transformed_values)
           ^^^^^^^^^^^^^^^^^^^^^^^^^^^^^^^^^^^^^^^^^^^^^^^^^^^^
  File "C:\Users\ghftr\AppData\Roaming\Python\Python311\site-packages\discord\app_commands\commands.py", line 846, in _do_call
    raise CommandInvokeError(self, e) from e
discord.app_commands.errors.CommandInvokeError: Command '모달' raised an exception: HTTPException: 400 Bad Request (error code: 50035): Invalid Form Body
In data.components.0.components.0: Value of field "type" must be one of (2, 3, 5, 6, 7, 8).
In data.components.1.components.0: Value of field "type" must be one of (2, 3, 5, 6, 7, 8).

2024-01-29 11:33:23 : Command '창설' raised an exception: TypeError: super(type, obj): obj must be an instance or subtype of type
Traceback (most recent call last):
  File "C:\Users\ghftr\AppData\Roaming\Python\Python311\site-packages\discord\app_commands\commands.py", line 827, in _do_call
    return await self._callback(self.binding, interaction, **params)  # type: ignore
           ^^^^^^^^^^^^^^^^^^^^^^^^^^^^^^^^^^^^^^^^^^^^^^^^^^^^^^^^^
  File "c:\Users\ghftr\Documents\GitHub\arislena-reborn\cogs\faction.py", line 26, in create
    if main_db.fetch("faction", f"user_id = {interaction.user.id}") and not checks.is_admin(interaction.user):
       ^^^^^^^^^^^^^^^^^^^^^^^^^^^^^^^^^^^^^^^^^^^^^^^^^^^^^^^^^^^^
  File "c:\Users\ghftr\Documents\GitHub\arislena-reborn\py_system\database.py", line 63, in fetch
    return convert_to_tableobj(table, data)
           ^^^^^^^^^^^^^^^^^^^^^^^^^^^^^^^^
  File "c:\Users\ghftr\Documents\GitHub\arislena-reborn\py_system\database.py", line 15, in convert_to_tableobj
    tableobj:TableObject = globals()[table_name.capitalize()]()
                           ^^^^^^^^^^^^^^^^^^^^^^^^^^^^^^^^^^^^
  File "<string>", line 7, in __init__
  File "c:\Users\ghftr\Documents\GitHub\arislena-reborn\py_system\tableobj.py", line 56, in __post_init__
    super().__post_init__()
    ^^^^^^^
TypeError: super(type, obj): obj must be an instance or subtype of type

The above exception was the direct cause of the following exception:

Traceback (most recent call last):
  File "C:\Users\ghftr\AppData\Roaming\Python\Python311\site-packages\discord\app_commands\tree.py", line 1248, in _call
    await command._invoke_with_namespace(interaction, namespace)
  File "C:\Users\ghftr\AppData\Roaming\Python\Python311\site-packages\discord\app_commands\commands.py", line 853, in _invoke_with_namespace
    return await self._do_call(interaction, transformed_values)
           ^^^^^^^^^^^^^^^^^^^^^^^^^^^^^^^^^^^^^^^^^^^^^^^^^^^^
  File "C:\Users\ghftr\AppData\Roaming\Python\Python311\site-packages\discord\app_commands\commands.py", line 842, in _do_call
    raise CommandInvokeError(self, e) from e
discord.app_commands.errors.CommandInvokeError: Command '창설' raised an exception: TypeError: super(type, obj): obj must be an instance or subtype of type

2024-01-29 11:37:41 : Command '창설' raised an exception: TypeError: super(type, obj): obj must be an instance or subtype of type
Traceback (most recent call last):
  File "C:\Users\ghftr\AppData\Roaming\Python\Python311\site-packages\discord\app_commands\commands.py", line 827, in _do_call
    return await self._callback(self.binding, interaction, **params)  # type: ignore
           ^^^^^^^^^^^^^^^^^^^^^^^^^^^^^^^^^^^^^^^^^^^^^^^^^^^^^^^^^
  File "C:\Users\ghftr\Documents\GitHub\arislena-reborn\cogs\faction.py", line 23, in create
    if main_db.fetch("faction", f"user_id = {interaction.user.id}") and not checks.is_admin(interaction.user):
       ^^^^^^^^^^^^^^^^^^^^^^^^^^^^^^^^^^^^^^^^^^^^^^^^^^^^^^^^^^^^
  File "C:\Users\ghftr\Documents\GitHub\arislena-reborn\py_system\database.py", line 63, in fetch
    return convert_to_tableobj(table, data)
           ^^^^^^^^^^^^^^^^^^^^^^^^^^^^^^^^
  File "C:\Users\ghftr\Documents\GitHub\arislena-reborn\py_system\database.py", line 15, in convert_to_tableobj
    tableobj:TableObject = globals()[table_name.capitalize()]()
                           ^^^^^^^^^^^^^^^^^^^^^^^^^^^^^^^^^^^^
  File "<string>", line 7, in __init__
  File "C:\Users\ghftr\Documents\GitHub\arislena-reborn\py_system\tableobj.py", line 56, in __post_init__
    super().__post_init__()
    ^^^^^^^
TypeError: super(type, obj): obj must be an instance or subtype of type

The above exception was the direct cause of the following exception:

Traceback (most recent call last):
  File "C:\Users\ghftr\AppData\Roaming\Python\Python311\site-packages\discord\app_commands\tree.py", line 1248, in _call
    await command._invoke_with_namespace(interaction, namespace)
  File "C:\Users\ghftr\AppData\Roaming\Python\Python311\site-packages\discord\app_commands\commands.py", line 853, in _invoke_with_namespace
    return await self._do_call(interaction, transformed_values)
           ^^^^^^^^^^^^^^^^^^^^^^^^^^^^^^^^^^^^^^^^^^^^^^^^^^^^
  File "C:\Users\ghftr\AppData\Roaming\Python\Python311\site-packages\discord\app_commands\commands.py", line 842, in _do_call
    raise CommandInvokeError(self, e) from e
discord.app_commands.errors.CommandInvokeError: Command '창설' raised an exception: TypeError: super(type, obj): obj must be an instance or subtype of type

2024-01-29 11:41:10 : Command '창설' raised an exception: TypeError: super(type, obj): obj must be an instance or subtype of type
Traceback (most recent call last):
  File "C:\Users\ghftr\AppData\Roaming\Python\Python311\site-packages\discord\app_commands\commands.py", line 827, in _do_call
    return await self._callback(self.binding, interaction, **params)  # type: ignore
           ^^^^^^^^^^^^^^^^^^^^^^^^^^^^^^^^^^^^^^^^^^^^^^^^^^^^^^^^^
  File "C:\Users\ghftr\Documents\GitHub\arislena-reborn\cogs\faction.py", line 23, in create
    if main_db.fetch("faction", f"user_id = {interaction.user.id}") and not checks.is_admin(interaction.user):
       ^^^^^^^^^^^^^^^^^^^^^^^^^^^^^^^^^^^^^^^^^^^^^^^^^^^^^^^^^^^^
  File "C:\Users\ghftr\Documents\GitHub\arislena-reborn\py_system\database.py", line 63, in fetch
    return convert_to_tableobj(table, data)
           ^^^^^^^^^^^^^^^^^^^^^^^^^^^^^^^^
  File "C:\Users\ghftr\Documents\GitHub\arislena-reborn\py_system\database.py", line 15, in convert_to_tableobj
    tableobj:TableObject = globals()[table_name.capitalize()]()
                           ^^^^^^^^^^^^^^^^^^^^^^^^^^^^^^^^^^^^
  File "<string>", line 7, in __init__
  File "C:\Users\ghftr\Documents\GitHub\arislena-reborn\py_system\tableobj.py", line 56, in __post_init__
    super().__post_init__()
    ^^^^^^^
TypeError: super(type, obj): obj must be an instance or subtype of type

The above exception was the direct cause of the following exception:

Traceback (most recent call last):
  File "C:\Users\ghftr\AppData\Roaming\Python\Python311\site-packages\discord\app_commands\tree.py", line 1248, in _call
    await command._invoke_with_namespace(interaction, namespace)
  File "C:\Users\ghftr\AppData\Roaming\Python\Python311\site-packages\discord\app_commands\commands.py", line 853, in _invoke_with_namespace
    return await self._do_call(interaction, transformed_values)
           ^^^^^^^^^^^^^^^^^^^^^^^^^^^^^^^^^^^^^^^^^^^^^^^^^^^^
  File "C:\Users\ghftr\AppData\Roaming\Python\Python311\site-packages\discord\app_commands\commands.py", line 842, in _do_call
    raise CommandInvokeError(self, e) from e
discord.app_commands.errors.CommandInvokeError: Command '창설' raised an exception: TypeError: super(type, obj): obj must be an instance or subtype of type

2024-01-29 11:42:47 : Command '창설' raised an exception: TypeError: super(type, obj): obj must be an instance or subtype of type
Traceback (most recent call last):
  File "C:\Users\ghftr\AppData\Roaming\Python\Python311\site-packages\discord\app_commands\commands.py", line 827, in _do_call
    return await self._callback(self.binding, interaction, **params)  # type: ignore
           ^^^^^^^^^^^^^^^^^^^^^^^^^^^^^^^^^^^^^^^^^^^^^^^^^^^^^^^^^
  File "C:\Users\ghftr\Documents\GitHub\arislena-reborn\cogs\faction.py", line 23, in create
    if main_db.fetch("faction", f"user_id = {interaction.user.id}") and not checks.is_admin(interaction.user):
       ^^^^^^^^^^^^^^^^^^^^^^^^^^^^^^^^^^^^^^^^^^^^^^^^^^^^^^^^^^^^
  File "C:\Users\ghftr\Documents\GitHub\arislena-reborn\py_system\database.py", line 63, in fetch
    return convert_to_tableobj(table, data)
           ^^^^^^^^^^^^^^^^^^^^^^^^^^^^^^^^
  File "C:\Users\ghftr\Documents\GitHub\arislena-reborn\py_system\database.py", line 15, in convert_to_tableobj
    tableobj:TableObject = globals()[table_name.capitalize()]()
                           ^^^^^^^^^^^^^^^^^^^^^^^^^^^^^^^^^^^^
  File "<string>", line 7, in __init__
  File "C:\Users\ghftr\Documents\GitHub\arislena-reborn\py_system\tableobj.py", line 57, in __post_init__
    super().__post_init__()
    ^^^^^^^
TypeError: super(type, obj): obj must be an instance or subtype of type

The above exception was the direct cause of the following exception:

Traceback (most recent call last):
  File "C:\Users\ghftr\AppData\Roaming\Python\Python311\site-packages\discord\app_commands\tree.py", line 1248, in _call
    await command._invoke_with_namespace(interaction, namespace)
  File "C:\Users\ghftr\AppData\Roaming\Python\Python311\site-packages\discord\app_commands\commands.py", line 853, in _invoke_with_namespace
    return await self._do_call(interaction, transformed_values)
           ^^^^^^^^^^^^^^^^^^^^^^^^^^^^^^^^^^^^^^^^^^^^^^^^^^^^
  File "C:\Users\ghftr\AppData\Roaming\Python\Python311\site-packages\discord\app_commands\commands.py", line 842, in _do_call
    raise CommandInvokeError(self, e) from e
discord.app_commands.errors.CommandInvokeError: Command '창설' raised an exception: TypeError: super(type, obj): obj must be an instance or subtype of type

2024-01-29 11:44:28 : Command '창설' raised an exception: BoxKeyError: "'Box' object has no attribute 'admin_role_id'"
Traceback (most recent call last):
  File "box\\box.py", line 592, in box.box.Box.__getitem__
KeyError: 'admin_role_id'

The above exception was the direct cause of the following exception:

Traceback (most recent call last):
  File "box\\box.py", line 631, in box.box.Box.__getattr__
  File "box\\box.py", line 619, in box.box.Box.__getitem__
box.exceptions.BoxKeyError: "'admin_role_id'"

During handling of the above exception, another exception occurred:

Traceback (most recent call last):
  File "box\\box.py", line 633, in box.box.Box.__getattr__
AttributeError: 'Box' object has no attribute 'admin_role_id'

The above exception was the direct cause of the following exception:

Traceback (most recent call last):
  File "C:\Users\ghftr\AppData\Roaming\Python\Python311\site-packages\discord\app_commands\commands.py", line 827, in _do_call
    return await self._callback(self.binding, interaction, **params)  # type: ignore
           ^^^^^^^^^^^^^^^^^^^^^^^^^^^^^^^^^^^^^^^^^^^^^^^^^^^^^^^^^
  File "C:\Users\ghftr\Documents\GitHub\arislena-reborn\cogs\faction.py", line 23, in create
    if main_db.fetch("faction", f"user_id = {interaction.user.id}") and not checks.is_admin(interaction.user):
                                                                            ^^^^^^^^^^^^^^^^^^^^^^^^^^^^^^^^^
  File "C:\Users\ghftr\Documents\GitHub\arislena-reborn\py_discord\checks.py", line 17, in is_admin
    if role.name == game_settings.admin_role_id[str(user.guild.id)]:
                    ^^^^^^^^^^^^^^^^^^^^^^^^^^^
  File "box\\box.py", line 647, in box.box.Box.__getattr__
box.exceptions.BoxKeyError: "'Box' object has no attribute 'admin_role_id'"

The above exception was the direct cause of the following exception:

Traceback (most recent call last):
  File "C:\Users\ghftr\AppData\Roaming\Python\Python311\site-packages\discord\app_commands\tree.py", line 1248, in _call
    await command._invoke_with_namespace(interaction, namespace)
  File "C:\Users\ghftr\AppData\Roaming\Python\Python311\site-packages\discord\app_commands\commands.py", line 853, in _invoke_with_namespace
    return await self._do_call(interaction, transformed_values)
           ^^^^^^^^^^^^^^^^^^^^^^^^^^^^^^^^^^^^^^^^^^^^^^^^^^^^
  File "C:\Users\ghftr\AppData\Roaming\Python\Python311\site-packages\discord\app_commands\commands.py", line 846, in _do_call
    raise CommandInvokeError(self, e) from e
discord.app_commands.errors.CommandInvokeError: Command '창설' raised an exception: BoxKeyError: "'Box' object has no attribute 'admin_role_id'"

2024-01-29 12:08:36 : Command '해산' raised an exception: TypeError: FactionDeleteButton.__init__() takes 2 positional arguments but 3 were given
Traceback (most recent call last):
  File "C:\Users\ghftr\AppData\Roaming\Python\Python311\site-packages\discord\app_commands\commands.py", line 827, in _do_call
    return await self._callback(self.binding, interaction, **params)  # type: ignore
           ^^^^^^^^^^^^^^^^^^^^^^^^^^^^^^^^^^^^^^^^^^^^^^^^^^^^^^^^^
  File "C:\Users\ghftr\Documents\GitHub\arislena-reborn\cogs\faction.py", line 60, in delete
    view=views.LookupView(
         ^^^^^^^^^^^^^^^^^
  File "C:\Users\ghftr\Documents\GitHub\arislena-reborn\py_discord\views.py", line 104, in __init__
    self.add_item(button_class(tableobj, display_column))
                  ^^^^^^^^^^^^^^^^^^^^^^^^^^^^^^^^^^^^^^
TypeError: FactionDeleteButton.__init__() takes 2 positional arguments but 3 were given

The above exception was the direct cause of the following exception:

Traceback (most recent call last):
  File "C:\Users\ghftr\AppData\Roaming\Python\Python311\site-packages\discord\app_commands\tree.py", line 1248, in _call
    await command._invoke_with_namespace(interaction, namespace)
  File "C:\Users\ghftr\AppData\Roaming\Python\Python311\site-packages\discord\app_commands\commands.py", line 853, in _invoke_with_namespace
    return await self._do_call(interaction, transformed_values)
           ^^^^^^^^^^^^^^^^^^^^^^^^^^^^^^^^^^^^^^^^^^^^^^^^^^^^
  File "C:\Users\ghftr\AppData\Roaming\Python\Python311\site-packages\discord\app_commands\commands.py", line 842, in _do_call
    raise CommandInvokeError(self, e) from e
discord.app_commands.errors.CommandInvokeError: Command '해산' raised an exception: TypeError: FactionDeleteButton.__init__() takes 2 positional arguments but 3 were given

2024-01-29 12:09:47 : Command '해산' raised an exception: TypeError: LookupButton.__init__() takes 2 positional arguments but 3 were given
Traceback (most recent call last):
  File "C:\Users\ghftr\AppData\Roaming\Python\Python311\site-packages\discord\app_commands\commands.py", line 827, in _do_call
    return await self._callback(self.binding, interaction, **params)  # type: ignore
           ^^^^^^^^^^^^^^^^^^^^^^^^^^^^^^^^^^^^^^^^^^^^^^^^^^^^^^^^^
  File "C:\Users\ghftr\Documents\GitHub\arislena-reborn\cogs\faction.py", line 60, in delete
    view=views.LookupView(
         ^^^^^^^^^^^^^^^^^
  File "C:\Users\ghftr\Documents\GitHub\arislena-reborn\py_discord\views.py", line 104, in __init__
    self.add_item(button_class(tableobj))
                  ^^^^^^^^^^^^^^^^^^^^^^
  File "C:\Users\ghftr\Documents\GitHub\arislena-reborn\py_discord\views.py", line 71, in __init__
    super().__init__(tableobj, "name")
TypeError: LookupButton.__init__() takes 2 positional arguments but 3 were given

The above exception was the direct cause of the following exception:

Traceback (most recent call last):
  File "C:\Users\ghftr\AppData\Roaming\Python\Python311\site-packages\discord\app_commands\tree.py", line 1248, in _call
    await command._invoke_with_namespace(interaction, namespace)
  File "C:\Users\ghftr\AppData\Roaming\Python\Python311\site-packages\discord\app_commands\commands.py", line 853, in _invoke_with_namespace
    return await self._do_call(interaction, transformed_values)
           ^^^^^^^^^^^^^^^^^^^^^^^^^^^^^^^^^^^^^^^^^^^^^^^^^^^^
  File "C:\Users\ghftr\AppData\Roaming\Python\Python311\site-packages\discord\app_commands\commands.py", line 842, in _do_call
    raise CommandInvokeError(self, e) from e
discord.app_commands.errors.CommandInvokeError: Command '해산' raised an exception: TypeError: LookupButton.__init__() takes 2 positional arguments but 3 were given

2024-01-29 17:11:28 : Command '열람' raised an exception: KeyError: 'User'
Traceback (most recent call last):
  File "C:\Users\ghftr\AppData\Roaming\Python\Python311\site-packages\discord\app_commands\commands.py", line 827, in _do_call
    return await self._callback(self.binding, interaction, **params)  # type: ignore
           ^^^^^^^^^^^^^^^^^^^^^^^^^^^^^^^^^^^^^^^^^^^^^^^^^^^^^^^^^
  File "c:\Users\ghftr\Documents\GitHub\arislena-reborn\cogs\user_management.py", line 74, in info
    my_info = main_db.fetch("user", f"discord_ID = {interaction.user.id}")
              ^^^^^^^^^^^^^^^^^^^^^^^^^^^^^^^^^^^^^^^^^^^^^^^^^^^^^^^^^^^^
  File "c:\Users\ghftr\Documents\GitHub\arislena-reborn\py_system\database.py", line 65, in fetch
    return convert_to_tableobj(table, data)
           ^^^^^^^^^^^^^^^^^^^^^^^^^^^^^^^^
  File "c:\Users\ghftr\Documents\GitHub\arislena-reborn\py_system\database.py", line 17, in convert_to_tableobj
    tableobj:TableObject = globals()[table_name]()
                           ~~~~~~~~~^^^^^^^^^^^^
KeyError: 'User'

The above exception was the direct cause of the following exception:

Traceback (most recent call last):
  File "C:\Users\ghftr\AppData\Roaming\Python\Python311\site-packages\discord\app_commands\tree.py", line 1248, in _call
    await command._invoke_with_namespace(interaction, namespace)
  File "C:\Users\ghftr\AppData\Roaming\Python\Python311\site-packages\discord\app_commands\commands.py", line 853, in _invoke_with_namespace
    return await self._do_call(interaction, transformed_values)
           ^^^^^^^^^^^^^^^^^^^^^^^^^^^^^^^^^^^^^^^^^^^^^^^^^^^^
  File "C:\Users\ghftr\AppData\Roaming\Python\Python311\site-packages\discord\app_commands\commands.py", line 846, in _do_call
    raise CommandInvokeError(self, e) from e
discord.app_commands.errors.CommandInvokeError: Command '열람' raised an exception: KeyError: 'User'

2024-01-29 17:17:18 : Command '열람' raised an exception: UnboundLocalError: cannot access local variable 'my_info' where it is not associated with a value
Traceback (most recent call last):
  File "C:\Users\ghftr\AppData\Roaming\Python\Python311\site-packages\discord\app_commands\commands.py", line 827, in _do_call
    return await self._callback(self.binding, interaction, **params)  # type: ignore
           ^^^^^^^^^^^^^^^^^^^^^^^^^^^^^^^^^^^^^^^^^^^^^^^^^^^^^^^^^
  File "C:\Users\ghftr\Documents\GitHub\arislena-reborn\cogs\user_management.py", line 88, in info
    embed=embeds.table_info(discord.Embed(title=f"{interaction.user.display_name}님의 정보", color=Colour.green()), my_info))
                                                                                                                ^^^^^^^
UnboundLocalError: cannot access local variable 'my_info' where it is not associated with a value

The above exception was the direct cause of the following exception:

Traceback (most recent call last):
  File "C:\Users\ghftr\AppData\Roaming\Python\Python311\site-packages\discord\app_commands\tree.py", line 1248, in _call
    await command._invoke_with_namespace(interaction, namespace)
  File "C:\Users\ghftr\AppData\Roaming\Python\Python311\site-packages\discord\app_commands\commands.py", line 853, in _invoke_with_namespace
    return await self._do_call(interaction, transformed_values)
           ^^^^^^^^^^^^^^^^^^^^^^^^^^^^^^^^^^^^^^^^^^^^^^^^^^^^
  File "C:\Users\ghftr\AppData\Roaming\Python\Python311\site-packages\discord\app_commands\commands.py", line 846, in _do_call
    raise CommandInvokeError(self, e) from e
discord.app_commands.errors.CommandInvokeError: Command '열람' raised an exception: UnboundLocalError: cannot access local variable 'my_info' where it is not associated with a value

2024-01-29 17:18:47 : Command '열람' raised an exception: KeyError: 'User'
Traceback (most recent call last):
  File "C:\Users\ghftr\AppData\Roaming\Python\Python311\site-packages\discord\app_commands\commands.py", line 827, in _do_call
    return await self._callback(self.binding, interaction, **params)  # type: ignore
           ^^^^^^^^^^^^^^^^^^^^^^^^^^^^^^^^^^^^^^^^^^^^^^^^^^^^^^^^^
  File "C:\Users\ghftr\Documents\GitHub\arislena-reborn\cogs\user_management.py", line 74, in info
  File "C:\Users\ghftr\Documents\GitHub\arislena-reborn\py_system\database.py", line 65, in fetch
    return convert_to_tableobj(table, data)
           ^^^^^^^^^^^^^^^^^^^^^^^^^^^^^^^^
  File "C:\Users\ghftr\Documents\GitHub\arislena-reborn\py_system\database.py", line 17, in convert_to_tableobj
    tableobj:TableObject = globals()[table_name]()
                           ~~~~~~~~~^^^^^^^^^^^^
KeyError: 'User'

The above exception was the direct cause of the following exception:

Traceback (most recent call last):
  File "C:\Users\ghftr\AppData\Roaming\Python\Python311\site-packages\discord\app_commands\tree.py", line 1248, in _call
    await command._invoke_with_namespace(interaction, namespace)
  File "C:\Users\ghftr\AppData\Roaming\Python\Python311\site-packages\discord\app_commands\commands.py", line 853, in _invoke_with_namespace
    return await self._do_call(interaction, transformed_values)
           ^^^^^^^^^^^^^^^^^^^^^^^^^^^^^^^^^^^^^^^^^^^^^^^^^^^^
  File "C:\Users\ghftr\AppData\Roaming\Python\Python311\site-packages\discord\app_commands\commands.py", line 846, in _do_call
    raise CommandInvokeError(self, e) from e
discord.app_commands.errors.CommandInvokeError: Command '열람' raised an exception: KeyError: 'User'

2024-02-22 22:58:58 : Command '등록' raised an exception: Exception: Database is not set.
Traceback (most recent call last):
  File "C:\Users\ghftr\AppData\Roaming\Python\Python311\site-packages\discord\app_commands\commands.py", line 827, in _do_call
    return await self._callback(self.binding, interaction, **params)  # type: ignore
           ^^^^^^^^^^^^^^^^^^^^^^^^^^^^^^^^^^^^^^^^^^^^^^^^^^^^^^^^^
  File "C:\Users\ghftr\Documents\GitHub\arislena-reborn\cogs\user_management.py", line 30, in register
    user.push()
  File "C:\Users\ghftr\Documents\GitHub\arislena-reborn\py_system\abstract.py", line 240, in push
    if not self._database: raise Exception("Database is not set.")
                           ^^^^^^^^^^^^^^^^^^^^^^^^^^^^^^^^^^^^^^^
Exception: Database is not set.

The above exception was the direct cause of the following exception:

Traceback (most recent call last):
  File "C:\Users\ghftr\AppData\Roaming\Python\Python311\site-packages\discord\app_commands\tree.py", line 1248, in _call
    await command._invoke_with_namespace(interaction, namespace)
  File "C:\Users\ghftr\AppData\Roaming\Python\Python311\site-packages\discord\app_commands\commands.py", line 853, in _invoke_with_namespace
    return await self._do_call(interaction, transformed_values)
           ^^^^^^^^^^^^^^^^^^^^^^^^^^^^^^^^^^^^^^^^^^^^^^^^^^^^
  File "C:\Users\ghftr\AppData\Roaming\Python\Python311\site-packages\discord\app_commands\commands.py", line 846, in _do_call
    raise CommandInvokeError(self, e) from e
discord.app_commands.errors.CommandInvokeError: Command '등록' raised an exception: Exception: Database is not set.

2024-02-22 23:03:02 : Command '등록' raised an exception: BoxKeyError: "'Box' object has no attribute 'user_role_id'"
Traceback (most recent call last):
  File "box\\box.py", line 592, in box.box.Box.__getitem__
KeyError: 'user_role_id'

The above exception was the direct cause of the following exception:

Traceback (most recent call last):
  File "box\\box.py", line 631, in box.box.Box.__getattr__
  File "box\\box.py", line 619, in box.box.Box.__getitem__
box.exceptions.BoxKeyError: "'user_role_id'"

During handling of the above exception, another exception occurred:

Traceback (most recent call last):
  File "box\\box.py", line 633, in box.box.Box.__getattr__
AttributeError: 'Box' object has no attribute 'user_role_id'

The above exception was the direct cause of the following exception:

Traceback (most recent call last):
  File "C:\Users\ghftr\AppData\Roaming\Python\Python311\site-packages\discord\app_commands\commands.py", line 827, in _do_call
    return await self._callback(self.binding, interaction, **params)  # type: ignore
           ^^^^^^^^^^^^^^^^^^^^^^^^^^^^^^^^^^^^^^^^^^^^^^^^^^^^^^^^^
  File "C:\Users\ghftr\Documents\GitHub\arislena-reborn\cogs\user_management.py", line 35, in register
    role = discord.utils.get(interaction.guild.roles, id=game_settings.user_role_id[str(interaction.guild.id)])
                                                         ^^^^^^^^^^^^^^^^^^^^^^^^^^
  File "box\\box.py", line 647, in box.box.Box.__getattr__
box.exceptions.BoxKeyError: "'Box' object has no attribute 'user_role_id'"

The above exception was the direct cause of the following exception:

Traceback (most recent call last):
  File "C:\Users\ghftr\AppData\Roaming\Python\Python311\site-packages\discord\app_commands\tree.py", line 1248, in _call
    await command._invoke_with_namespace(interaction, namespace)
  File "C:\Users\ghftr\AppData\Roaming\Python\Python311\site-packages\discord\app_commands\commands.py", line 853, in _invoke_with_namespace
    return await self._do_call(interaction, transformed_values)
           ^^^^^^^^^^^^^^^^^^^^^^^^^^^^^^^^^^^^^^^^^^^^^^^^^^^^
  File "C:\Users\ghftr\AppData\Roaming\Python\Python311\site-packages\discord\app_commands\commands.py", line 846, in _do_call
    raise CommandInvokeError(self, e) from e
discord.app_commands.errors.CommandInvokeError: Command '등록' raised an exception: BoxKeyError: "'Box' object has no attribute 'user_role_id'"

2024-02-23 19:12:44 : Command '열람' raised an exception: Exception: Database is not set.
Traceback (most recent call last):
  File "C:\Users\ghftr\AppData\Roaming\Python\Python311\site-packages\discord\app_commands\commands.py", line 827, in _do_call
    return await self._callback(self.binding, interaction, **params)  # type: ignore
           ^^^^^^^^^^^^^^^^^^^^^^^^^^^^^^^^^^^^^^^^^^^^^^^^^^^^^^^^^
  File "C:\Users\ghftr\Documents\GitHub\arislena-reborn\cogs\user_management.py", line 76, in info
    user.pull(discord_id = interaction.user.id)
  File "C:\Users\ghftr\Documents\GitHub\arislena-reborn\py_base\abstract.py", line 244, in pull
    raise Exception("Database is not set.")
Exception: Database is not set.

The above exception was the direct cause of the following exception:

Traceback (most recent call last):
  File "C:\Users\ghftr\AppData\Roaming\Python\Python311\site-packages\discord\app_commands\tree.py", line 1248, in _call
    await command._invoke_with_namespace(interaction, namespace)
  File "C:\Users\ghftr\AppData\Roaming\Python\Python311\site-packages\discord\app_commands\commands.py", line 853, in _invoke_with_namespace
    return await self._do_call(interaction, transformed_values)
           ^^^^^^^^^^^^^^^^^^^^^^^^^^^^^^^^^^^^^^^^^^^^^^^^^^^^
  File "C:\Users\ghftr\AppData\Roaming\Python\Python311\site-packages\discord\app_commands\commands.py", line 846, in _do_call
    raise CommandInvokeError(self, e) from e
discord.app_commands.errors.CommandInvokeError: Command '열람' raised an exception: Exception: Database is not set.

2024-02-23 20:03:20 : Command '열람' raised an exception: TypeError: 'NoneType' object is not iterable
Traceback (most recent call last):
  File "C:\Users\ghftr\AppData\Roaming\Python\Python311\site-packages\discord\app_commands\commands.py", line 827, in _do_call
    return await self._callback(self.binding, interaction, **params)  # type: ignore
           ^^^^^^^^^^^^^^^^^^^^^^^^^^^^^^^^^^^^^^^^^^^^^^^^^^^^^^^^^
  File "C:\Users\ghftr\Documents\GitHub\arislena-reborn\cogs\user_management.py", line 78, in info
    embed=embeds.table_info(
          ^^^^^^^^^^^^^^^^^^
  File "C:\Users\ghftr\Documents\GitHub\arislena-reborn\py_discord\embeds.py", line 55, in table_info
    for key, value in table_obj.kr_dict.items():
                      ^^^^^^^^^^^^^^^^^
  File "C:\Users\ghftr\Documents\GitHub\arislena-reborn\py_base\abstract.py", line 146, in kr_dict
    return dict(zip(self.kr_list, self.items.values()))
                ^^^^^^^^^^^^^^^^^^^^^^^^^^^^^^^^^^^^^^
TypeError: 'NoneType' object is not iterable

The above exception was the direct cause of the following exception:

Traceback (most recent call last):
  File "C:\Users\ghftr\AppData\Roaming\Python\Python311\site-packages\discord\app_commands\tree.py", line 1248, in _call
    await command._invoke_with_namespace(interaction, namespace)
  File "C:\Users\ghftr\AppData\Roaming\Python\Python311\site-packages\discord\app_commands\commands.py", line 853, in _invoke_with_namespace
    return await self._do_call(interaction, transformed_values)
           ^^^^^^^^^^^^^^^^^^^^^^^^^^^^^^^^^^^^^^^^^^^^^^^^^^^^
  File "C:\Users\ghftr\AppData\Roaming\Python\Python311\site-packages\discord\app_commands\commands.py", line 842, in _do_call
    raise CommandInvokeError(self, e) from e
discord.app_commands.errors.CommandInvokeError: Command '열람' raised an exception: TypeError: 'NoneType' object is not iterable

2024-02-25 23:50:43 : Command '열람' raised an exception: AttributeError: 'Territory' object has no attribute 'user_id'
Traceback (most recent call last):
  File "C:\Users\ghftr\AppData\Roaming\Python\Python311\site-packages\discord\app_commands\commands.py", line 827, in _do_call
    return await self._callback(self.binding, interaction, **params)  # type: ignore
           ^^^^^^^^^^^^^^^^^^^^^^^^^^^^^^^^^^^^^^^^^^^^^^^^^^^^^^^^^
  File "C:\Users\ghftr\Documents\GitHub\arislena-reborn\cogs\territory.py", line 26, in lookup
    view=views.LookupView(
         ^^^^^^^^^^^^^^^^^
  File "C:\Users\ghftr\Documents\GitHub\arislena-reborn\py_discord\views.py", line 176, in __init__
    self.add_item(button_class(tableobj, **kwargs))
                  ^^^^^^^^^^^^^^^^^^^^^^^^^^^^^^^^
  File "C:\Users\ghftr\Documents\GitHub\arislena-reborn\py_discord\views.py", line 98, in __init__
    user = discord.utils.get(interaction.guild.members, id = faction.user_id)
                                                             ^^^^^^^^^^^^^^^
AttributeError: 'Territory' object has no attribute 'user_id'

The above exception was the direct cause of the following exception:

Traceback (most recent call last):
  File "C:\Users\ghftr\AppData\Roaming\Python\Python311\site-packages\discord\app_commands\tree.py", line 1248, in _call
    await command._invoke_with_namespace(interaction, namespace)
  File "C:\Users\ghftr\AppData\Roaming\Python\Python311\site-packages\discord\app_commands\commands.py", line 853, in _invoke_with_namespace
    return await self._do_call(interaction, transformed_values)
           ^^^^^^^^^^^^^^^^^^^^^^^^^^^^^^^^^^^^^^^^^^^^^^^^^^^^
  File "C:\Users\ghftr\AppData\Roaming\Python\Python311\site-packages\discord\app_commands\commands.py", line 846, in _do_call
    raise CommandInvokeError(self, e) from e
discord.app_commands.errors.CommandInvokeError: Command '열람' raised an exception: AttributeError: 'Territory' object has no attribute 'user_id'

2024-02-26 22:11:01 : Command '열람' raised an exception: KeyError: 'i'
Traceback (most recent call last):
  File "C:\Users\ghftr\AppData\Roaming\Python\Python311\site-packages\discord\app_commands\commands.py", line 827, in _do_call
    return await self._callback(self.binding, interaction, **params)  # type: ignore
           ^^^^^^^^^^^^^^^^^^^^^^^^^^^^^^^^^^^^^^^^^^^^^^^^^^^^^^^^^
  File "C:\Users\ghftr\Documents\GitHub\arislena-reborn\cogs\territory.py", line 27, in lookup
    view=views.LookupView(
         ^^^^^^^^^^^^^^^^^
  File "C:\Users\ghftr\Documents\GitHub\arislena-reborn\py_discord\views.py", line 176, in __init__
    self.add_item(button_class(tableobj, **kwargs))
                  ^^^^^^^^^^^^^^^^^^^^^^^^^^^^^^^^
  File "C:\Users\ghftr\Documents\GitHub\arislena-reborn\py_discord\views.py", line 109, in __init__
    faction = Faction.from_database(main_db, id = territory.faction_id)
              ^^^^^^^^^^^^^^^^^^^^^^^^^^^^^^^^^^^^^^^^^^^^^^^^^^^^^^^^^
  File "C:\Users\ghftr\Documents\GitHub\arislena-reborn\py_base\abstract.py", line 128, in from_database
    new_obj.pull(*raw_statements, **statements)
  File "C:\Users\ghftr\Documents\GitHub\arislena-reborn\py_base\abstract.py", line 222, in pull
    annotation = str(self.__annotations__[key]).removeprefix("<").removesuffix(">").split("'")
                     ~~~~~~~~~~~~~~~~~~~~^^^^^
KeyError: 'i'

The above exception was the direct cause of the following exception:

Traceback (most recent call last):
  File "C:\Users\ghftr\AppData\Roaming\Python\Python311\site-packages\discord\app_commands\tree.py", line 1248, in _call
    await command._invoke_with_namespace(interaction, namespace)
  File "C:\Users\ghftr\AppData\Roaming\Python\Python311\site-packages\discord\app_commands\commands.py", line 853, in _invoke_with_namespace
    return await self._do_call(interaction, transformed_values)
           ^^^^^^^^^^^^^^^^^^^^^^^^^^^^^^^^^^^^^^^^^^^^^^^^^^^^
  File "C:\Users\ghftr\AppData\Roaming\Python\Python311\site-packages\discord\app_commands\commands.py", line 846, in _do_call
    raise CommandInvokeError(self, e) from e
discord.app_commands.errors.CommandInvokeError: Command '열람' raised an exception: KeyError: 'i'

2024-02-26 22:49:50 : Command '열람' raised an exception: ValueError: None is not a valid TerritoryCategory
Traceback (most recent call last):
  File "C:\Users\ghftr\AppData\Roaming\Python\Python311\site-packages\discord\app_commands\commands.py", line 827, in _do_call
    return await self._callback(self.binding, interaction, **params)  # type: ignore
           ^^^^^^^^^^^^^^^^^^^^^^^^^^^^^^^^^^^^^^^^^^^^^^^^^^^^^^^^^
  File "C:\Users\ghftr\Documents\GitHub\arislena-reborn\cogs\territory.py", line 22, in lookup
    territory_list = [deserialize(Territory, data) for data in territory_data_list]
                     ^^^^^^^^^^^^^^^^^^^^^^^^^^^^^^^^^^^^^^^^^^^^^^^^^^^^^^^^^^^^^^
  File "C:\Users\ghftr\Documents\GitHub\arislena-reborn\cogs\territory.py", line 22, in <listcomp>
    territory_list = [deserialize(Territory, data) for data in territory_data_list]
                      ^^^^^^^^^^^^^^^^^^^^^^^^^^^^
  File "C:\Users\ghftr\Documents\GitHub\arislena-reborn\py_system\tableobj.py", line 36, in deserialize
    tableobj.__setattr__(key, get_enum(class_name, sqlite_row[key]))
                              ^^^^^^^^^^^^^^^^^^^^^^^^^^^^^^^^^^^^^
  File "C:\Users\ghftr\Documents\GitHub\arislena-reborn\py_base\ari_enum.py", line 10, in get_enum
    return globals()[enum_class_name](value)
           ^^^^^^^^^^^^^^^^^^^^^^^^^^^^^^^^^
  File "c:\Program Files\Python311\Lib\enum.py", line 712, in __call__
    return cls.__new__(cls, value)
           ^^^^^^^^^^^^^^^^^^^^^^^
  File "c:\Program Files\Python311\Lib\enum.py", line 1135, in __new__
    raise ve_exc
ValueError: None is not a valid TerritoryCategory

The above exception was the direct cause of the following exception:

Traceback (most recent call last):
  File "C:\Users\ghftr\AppData\Roaming\Python\Python311\site-packages\discord\app_commands\tree.py", line 1248, in _call
    await command._invoke_with_namespace(interaction, namespace)
  File "C:\Users\ghftr\AppData\Roaming\Python\Python311\site-packages\discord\app_commands\commands.py", line 853, in _invoke_with_namespace
    return await self._do_call(interaction, transformed_values)
           ^^^^^^^^^^^^^^^^^^^^^^^^^^^^^^^^^^^^^^^^^^^^^^^^^^^^
  File "C:\Users\ghftr\AppData\Roaming\Python\Python311\site-packages\discord\app_commands\commands.py", line 846, in _do_call
    raise CommandInvokeError(self, e) from e
discord.app_commands.errors.CommandInvokeError: Command '열람' raised an exception: ValueError: None is not a valid TerritoryCategory

2024-03-11 15:26:44 : Command '건설' raised an exception: AttributeError: 'sqlite3.Row' object has no attribute 'faction_id'
Traceback (most recent call last):
  File "C:\Users\PC\AppData\Roaming\Python\Python311\site-packages\discord\app_commands\commands.py", line 861, in _do_call
    return await self._callback(self.binding, interaction, **params)  # type: ignore
           ^^^^^^^^^^^^^^^^^^^^^^^^^^^^^^^^^^^^^^^^^^^^^^^^^^^^^^^^^
  File "C:\Users\PC\Documents\GitHub\arislena-reborn\cogs\territory.py", line 89, in build
    view=views.LookupView(
         ^^^^^^^^^^^^^^^^^
  File "C:\Users\PC\Documents\GitHub\arislena-reborn\py_discord\views.py", line 188, in __init__
    self.add_item(button_class(tableobj, **kwargs))
                  ^^^^^^^^^^^^^^^^^^^^^^^^^^^^^^^^
  File "C:\Users\PC\Documents\GitHub\arislena-reborn\py_discord\views.py", line 121, in __init__
    super().__init__(territory, bot = bot, interaction = interaction)
  File "C:\Users\PC\Documents\GitHub\arislena-reborn\py_discord\views.py", line 110, in __init__
    self.faction = Faction.from_database(main_db, id = territory.faction_id)
                                                       ^^^^^^^^^^^^^^^^^^^^
AttributeError: 'sqlite3.Row' object has no attribute 'faction_id'

The above exception was the direct cause of the following exception:

Traceback (most recent call last):
  File "C:\Users\PC\AppData\Roaming\Python\Python311\site-packages\discord\app_commands\tree.py", line 1242, in _call
    await command._invoke_with_namespace(interaction, namespace)
  File "C:\Users\PC\AppData\Roaming\Python\Python311\site-packages\discord\app_commands\commands.py", line 887, in _invoke_with_namespace
    return await self._do_call(interaction, transformed_values)
           ^^^^^^^^^^^^^^^^^^^^^^^^^^^^^^^^^^^^^^^^^^^^^^^^^^^^
  File "C:\Users\PC\AppData\Roaming\Python\Python311\site-packages\discord\app_commands\commands.py", line 880, in _do_call
    raise CommandInvokeError(self, e) from e
discord.app_commands.errors.CommandInvokeError: Command '건설' raised an exception: AttributeError: 'sqlite3.Row' object has no attribute 'faction_id'

2024-03-11 16:24:58 : Command '선택지' raised an exception: AttributeError: 'BuildingSelect' object has no attribute 'to_components'
Traceback (most recent call last):
  File "C:\Users\PC\AppData\Roaming\Python\Python311\site-packages\discord\app_commands\commands.py", line 861, in _do_call
    return await self._callback(self.binding, interaction, **params)  # type: ignore
           ^^^^^^^^^^^^^^^^^^^^^^^^^^^^^^^^^^^^^^^^^^^^^^^^^^^^^^^^^
  File "C:\Users\PC\Documents\GitHub\arislena-reborn\cogs\test.py", line 26, in test2
    await interaction.response.send_message("선택지를 선택해봐!", view=BuildingSelect())
  File "C:\Users\PC\AppData\Roaming\Python\Python311\site-packages\discord\interactions.py", line 754, in send_message
    params = interaction_message_response_params(
             ^^^^^^^^^^^^^^^^^^^^^^^^^^^^^^^^^^^^
  File "C:\Users\PC\AppData\Roaming\Python\Python311\site-packages\discord\webhook\async_.py", line 577, in interaction_message_response_params
    data['components'] = view.to_components()
                         ^^^^^^^^^^^^^^^^^^
AttributeError: 'BuildingSelect' object has no attribute 'to_components'

The above exception was the direct cause of the following exception:

Traceback (most recent call last):
  File "C:\Users\PC\AppData\Roaming\Python\Python311\site-packages\discord\app_commands\tree.py", line 1242, in _call
    await command._invoke_with_namespace(interaction, namespace)
  File "C:\Users\PC\AppData\Roaming\Python\Python311\site-packages\discord\app_commands\commands.py", line 887, in _invoke_with_namespace
    return await self._do_call(interaction, transformed_values)
           ^^^^^^^^^^^^^^^^^^^^^^^^^^^^^^^^^^^^^^^^^^^^^^^^^^^^
  File "C:\Users\PC\AppData\Roaming\Python\Python311\site-packages\discord\app_commands\commands.py", line 880, in _do_call
    raise CommandInvokeError(self, e) from e
discord.app_commands.errors.CommandInvokeError: Command '선택지' raised an exception: AttributeError: 'BuildingSelect' object has no attribute 'to_components'

2024-03-13 14:51:29 : Command '정화' raised an exception: TypeError: TerritorySafety.max_value() takes 0 positional arguments but 1 was given
Traceback (most recent call last):
  File "C:\Users\PC\AppData\Roaming\Python\Python311\site-packages\discord\app_commands\commands.py", line 861, in _do_call
    return await self._callback(self.binding, interaction, **params)  # type: ignore
           ^^^^^^^^^^^^^^^^^^^^^^^^^^^^^^^^^^^^^^^^^^^^^^^^^^^^^^^^^
  File "C:\Users\PC\Documents\GitHub\arislena-reborn\cogs\territory.py", line 73, in purify
    if territory.safety == TerritorySafety.max_value():
                           ^^^^^^^^^^^^^^^^^^^^^^^^^^^
TypeError: TerritorySafety.max_value() takes 0 positional arguments but 1 was given

The above exception was the direct cause of the following exception:

Traceback (most recent call last):
  File "C:\Users\PC\AppData\Roaming\Python\Python311\site-packages\discord\app_commands\tree.py", line 1242, in _call
    await command._invoke_with_namespace(interaction, namespace)
  File "C:\Users\PC\AppData\Roaming\Python\Python311\site-packages\discord\app_commands\commands.py", line 887, in _invoke_with_namespace
    return await self._do_call(interaction, transformed_values)
           ^^^^^^^^^^^^^^^^^^^^^^^^^^^^^^^^^^^^^^^^^^^^^^^^^^^^
  File "C:\Users\PC\AppData\Roaming\Python\Python311\site-packages\discord\app_commands\commands.py", line 876, in _do_call
    raise CommandInvokeError(self, e) from e
discord.app_commands.errors.CommandInvokeError: Command '정화' raised an exception: TypeError: TerritorySafety.max_value() takes 0 positional arguments but 1 was given

2024-03-19 19:18:14 : Command '모병' raised an exception: OperationalError: no such table: command_counter
Traceback (most recent call last):
  File "C:\Users\PC\AppData\Roaming\Python\Python311\site-packages\discord\app_commands\commands.py", line 861, in _do_call
    return await self._callback(self.binding, interaction, **params)  # type: ignore
           ^^^^^^^^^^^^^^^^^^^^^^^^^^^^^^^^^^^^^^^^^^^^^^^^^^^^^^^^^
  File "C:\Users\PC\Documents\GitHub\arislena-reborn\cogs\faction.py", line 105, in recruit
    cmd_counter = faction.get_command_counter()
                  ^^^^^^^^^^^^^^^^^^^^^^^^^^^^^
  File "C:\Users\PC\Documents\GitHub\arislena-reborn\py_system\tableobj.py", line 340, in get_command_counter
    cc = self._database.fetch("command_counter", faction_id=self.id)
         ^^^^^^^^^^^^^^^^^^^^^^^^^^^^^^^^^^^^^^^^^^^^^^^^^^^^^^^^^^^
  File "C:\Users\PC\Documents\GitHub\arislena-reborn\py_base\dbmanager.py", line 60, in fetch
    self.cursor.execute(sql)
sqlite3.OperationalError: no such table: command_counter

The above exception was the direct cause of the following exception:

Traceback (most recent call last):
  File "C:\Users\PC\AppData\Roaming\Python\Python311\site-packages\discord\app_commands\tree.py", line 1242, in _call
    await command._invoke_with_namespace(interaction, namespace)
  File "C:\Users\PC\AppData\Roaming\Python\Python311\site-packages\discord\app_commands\commands.py", line 887, in _invoke_with_namespace
    return await self._do_call(interaction, transformed_values)
           ^^^^^^^^^^^^^^^^^^^^^^^^^^^^^^^^^^^^^^^^^^^^^^^^^^^^
  File "C:\Users\PC\AppData\Roaming\Python\Python311\site-packages\discord\app_commands\commands.py", line 880, in _do_call
    raise CommandInvokeError(self, e) from e
discord.app_commands.errors.CommandInvokeError: Command '모병' raised an exception: OperationalError: no such table: command_counter

2024-03-19 19:18:54 : Command '모병' raised an exception: OperationalError: no such column: building_category
Traceback (most recent call last):
  File "C:\Users\PC\AppData\Roaming\Python\Python311\site-packages\discord\app_commands\commands.py", line 861, in _do_call
    return await self._callback(self.binding, interaction, **params)  # type: ignore
           ^^^^^^^^^^^^^^^^^^^^^^^^^^^^^^^^^^^^^^^^^^^^^^^^^^^^^^^^^
  File "C:\Users\PC\Documents\GitHub\arislena-reborn\cogs\faction.py", line 107, in recruit
    recruit_limit = main_db.fetch_many(
                    ^^^^^^^^^^^^^^^^^^^
  File "C:\Users\PC\Documents\GitHub\arislena-reborn\py_base\dbmanager.py", line 108, in fetch_many
    self.cursor.execute(sql)
sqlite3.OperationalError: no such column: building_category

The above exception was the direct cause of the following exception:

Traceback (most recent call last):
  File "C:\Users\PC\AppData\Roaming\Python\Python311\site-packages\discord\app_commands\tree.py", line 1242, in _call
    await command._invoke_with_namespace(interaction, namespace)
  File "C:\Users\PC\AppData\Roaming\Python\Python311\site-packages\discord\app_commands\commands.py", line 887, in _invoke_with_namespace
    return await self._do_call(interaction, transformed_values)
           ^^^^^^^^^^^^^^^^^^^^^^^^^^^^^^^^^^^^^^^^^^^^^^^^^^^^
  File "C:\Users\PC\AppData\Roaming\Python\Python311\site-packages\discord\app_commands\commands.py", line 880, in _do_call
    raise CommandInvokeError(self, e) from e
discord.app_commands.errors.CommandInvokeError: Command '모병' raised an exception: OperationalError: no such column: building_category

2024-03-19 19:24:26 : Command '모병' raised an exception: OperationalError: near "<": syntax error
Traceback (most recent call last):
  File "C:\Users\PC\AppData\Roaming\Python\Python311\site-packages\discord\app_commands\commands.py", line 861, in _do_call
    return await self._callback(self.binding, interaction, **params)  # type: ignore
           ^^^^^^^^^^^^^^^^^^^^^^^^^^^^^^^^^^^^^^^^^^^^^^^^^^^^^^^^^
  File "C:\Users\PC\Documents\GitHub\arislena-reborn\cogs\faction.py", line 110, in recruit
    recruit_limit += main_db.fetch_many(
                     ^^^^^^^^^^^^^^^^^^^
  File "C:\Users\PC\Documents\GitHub\arislena-reborn\py_base\dbmanager.py", line 108, in fetch_many
    self.cursor.execute(sql)
sqlite3.OperationalError: near "<": syntax error

The above exception was the direct cause of the following exception:

Traceback (most recent call last):
  File "C:\Users\PC\AppData\Roaming\Python\Python311\site-packages\discord\app_commands\tree.py", line 1242, in _call
    await command._invoke_with_namespace(interaction, namespace)
  File "C:\Users\PC\AppData\Roaming\Python\Python311\site-packages\discord\app_commands\commands.py", line 887, in _invoke_with_namespace
    return await self._do_call(interaction, transformed_values)
           ^^^^^^^^^^^^^^^^^^^^^^^^^^^^^^^^^^^^^^^^^^^^^^^^^^^^
  File "C:\Users\PC\AppData\Roaming\Python\Python311\site-packages\discord\app_commands\commands.py", line 880, in _do_call
    raise CommandInvokeError(self, e) from e
discord.app_commands.errors.CommandInvokeError: Command '모병' raised an exception: OperationalError: near "<": syntax error

2024-03-19 19:26:09 : Command '모병' raised an exception: OperationalError: near "<": syntax error
Traceback (most recent call last):
  File "C:\Users\PC\AppData\Roaming\Python\Python311\site-packages\discord\app_commands\commands.py", line 861, in _do_call
    return await self._callback(self.binding, interaction, **params)  # type: ignore
           ^^^^^^^^^^^^^^^^^^^^^^^^^^^^^^^^^^^^^^^^^^^^^^^^^^^^^^^^^
  File "C:\Users\PC\Documents\GitHub\arislena-reborn\cogs\faction.py", line 110, in recruit
    recruit_limit += main_db.fetch_many(
                     ^^^^^^^^^^^^^^^^^^^
  File "C:\Users\PC\Documents\GitHub\arislena-reborn\py_base\dbmanager.py", line 109, in fetch_many
    self.cursor.execute(sql)
sqlite3.OperationalError: near "<": syntax error

The above exception was the direct cause of the following exception:

Traceback (most recent call last):
  File "C:\Users\PC\AppData\Roaming\Python\Python311\site-packages\discord\app_commands\tree.py", line 1242, in _call
    await command._invoke_with_namespace(interaction, namespace)
  File "C:\Users\PC\AppData\Roaming\Python\Python311\site-packages\discord\app_commands\commands.py", line 887, in _invoke_with_namespace
    return await self._do_call(interaction, transformed_values)
           ^^^^^^^^^^^^^^^^^^^^^^^^^^^^^^^^^^^^^^^^^^^^^^^^^^^^
  File "C:\Users\PC\AppData\Roaming\Python\Python311\site-packages\discord\app_commands\commands.py", line 880, in _do_call
    raise CommandInvokeError(self, e) from e
discord.app_commands.errors.CommandInvokeError: Command '모병' raised an exception: OperationalError: near "<": syntax error

2024-03-19 19:27:27 : Command '모병' raised an exception: TypeError: 'int' object is not iterable
Traceback (most recent call last):
  File "C:\Users\PC\AppData\Roaming\Python\Python311\site-packages\discord\app_commands\commands.py", line 861, in _do_call
    return await self._callback(self.binding, interaction, **params)  # type: ignore
           ^^^^^^^^^^^^^^^^^^^^^^^^^^^^^^^^^^^^^^^^^^^^^^^^^^^^^^^^^
  File "C:\Users\PC\Documents\GitHub\arislena-reborn\cogs\faction.py", line 121, in recruit
    for _ in try_count:
TypeError: 'int' object is not iterable

The above exception was the direct cause of the following exception:

Traceback (most recent call last):
  File "C:\Users\PC\AppData\Roaming\Python\Python311\site-packages\discord\app_commands\tree.py", line 1242, in _call
    await command._invoke_with_namespace(interaction, namespace)
  File "C:\Users\PC\AppData\Roaming\Python\Python311\site-packages\discord\app_commands\commands.py", line 887, in _invoke_with_namespace
    return await self._do_call(interaction, transformed_values)
           ^^^^^^^^^^^^^^^^^^^^^^^^^^^^^^^^^^^^^^^^^^^^^^^^^^^^
  File "C:\Users\PC\AppData\Roaming\Python\Python311\site-packages\discord\app_commands\commands.py", line 876, in _do_call
    raise CommandInvokeError(self, e) from e
discord.app_commands.errors.CommandInvokeError: Command '모병' raised an exception: TypeError: 'int' object is not iterable

2024-03-21 12:08:14 : Command '턴넘기기' raised an exception: ValueError: enum의 값이 None입니다. 데이터에서 값을 확인해주세요.
Traceback (most recent call last):
  File "C:\Users\PC\AppData\Roaming\Python\Python311\site-packages\discord\app_commands\commands.py", line 861, in _do_call
    return await self._callback(self.binding, interaction, **params)  # type: ignore
           ^^^^^^^^^^^^^^^^^^^^^^^^^^^^^^^^^^^^^^^^^^^^^^^^^^^^^^^^^
  File "C:\Users\PC\Documents\GitHub\arislena-reborn\cogs\test.py", line 41, in elapse_turn
    schedule_manager.end_turn()
  File "C:\Users\PC\Documents\GitHub\arislena-reborn\py_system\schedule_manager.py", line 101, in end_turn
    self.execute_after_turn_end()
  File "C:\Users\PC\Documents\GitHub\arislena-reborn\py_system\schedule_manager.py", line 167, in execute_after_turn_end
    cc_list = [tableobj.CommandCounter.from_data(cc) for cc in self.main_db.fetch_all(tableobj.CommandCounter.__name__)]
              ^^^^^^^^^^^^^^^^^^^^^^^^^^^^^^^^^^^^^^^^^^^^^^^^^^^^^^^^^^^^^^^^^^^^^^^^^^^^^^^^^^^^^^^^^^^^^^^^^^^^^^^^^^
  File "C:\Users\PC\Documents\GitHub\arislena-reborn\py_system\schedule_manager.py", line 167, in <listcomp>
    cc_list = [tableobj.CommandCounter.from_data(cc) for cc in self.main_db.fetch_all(tableobj.CommandCounter.__name__)]
               ^^^^^^^^^^^^^^^^^^^^^^^^^^^^^^^^^^^^^
  File "C:\Users\PC\Documents\GitHub\arislena-reborn\py_system\abstract.py", line 129, in from_data
    new_obj._set_attributes_from_sqlite_row(sqlite_row)
  File "C:\Users\PC\Documents\GitHub\arislena-reborn\py_system\abstract.py", line 95, in _set_attributes_from_sqlite_row
    setattr(self, key, get_enum(class_name, row[key]))
                       ^^^^^^^^^^^^^^^^^^^^^^^^^^^^^^
  File "C:\Users\PC\Documents\GitHub\arislena-reborn\py_base\ari_enum.py", line 13, in get_enum
    if value is None: raise ValueError("enum의 값이 None입니다. 데이터에서 값을 확인해주세요.")
                      ^^^^^^^^^^^^^^^^^^^^^^^^^^^^^^^^^^^^^^^^^^^^^^^^^^^^^^^^^^^^^^^^^^^^^^^^^
ValueError: enum의 값이 None입니다. 데이터에서 값을 확인해주세요.

The above exception was the direct cause of the following exception:

Traceback (most recent call last):
  File "C:\Users\PC\AppData\Roaming\Python\Python311\site-packages\discord\app_commands\tree.py", line 1242, in _call
    await command._invoke_with_namespace(interaction, namespace)
  File "C:\Users\PC\AppData\Roaming\Python\Python311\site-packages\discord\app_commands\commands.py", line 887, in _invoke_with_namespace
    return await self._do_call(interaction, transformed_values)
           ^^^^^^^^^^^^^^^^^^^^^^^^^^^^^^^^^^^^^^^^^^^^^^^^^^^^
  File "C:\Users\PC\AppData\Roaming\Python\Python311\site-packages\discord\app_commands\commands.py", line 880, in _do_call
    raise CommandInvokeError(self, e) from e
discord.app_commands.errors.CommandInvokeError: Command '턴넘기기' raised an exception: ValueError: enum의 값이 None입니다. 데이터에서 값을 확인해주세요.

2024-03-21 12:25:22 : Command '모집' raised an exception: OperationalError: no such column: discriminator
Traceback (most recent call last):
  File "C:\Users\PC\AppData\Roaming\Python\Python311\site-packages\discord\app_commands\commands.py", line 861, in _do_call
    return await self._callback(self.binding, interaction, **params)  # type: ignore
           ^^^^^^^^^^^^^^^^^^^^^^^^^^^^^^^^^^^^^^^^^^^^^^^^^^^^^^^^^
  File "C:\Users\PC\Documents\GitHub\arislena-reborn\cogs\crew.py", line 37, in recruit
    recruit_limit += main_db.fetch_many(
                     ^^^^^^^^^^^^^^^^^^^
  File "C:\Users\PC\Documents\GitHub\arislena-reborn\py_base\dbmanager.py", line 113, in fetch_many
    self.cursor.execute(sql)
sqlite3.OperationalError: no such column: discriminator

The above exception was the direct cause of the following exception:

Traceback (most recent call last):
  File "C:\Users\PC\AppData\Roaming\Python\Python311\site-packages\discord\app_commands\tree.py", line 1242, in _call
    await command._invoke_with_namespace(interaction, namespace)
  File "C:\Users\PC\AppData\Roaming\Python\Python311\site-packages\discord\app_commands\commands.py", line 887, in _invoke_with_namespace
    return await self._do_call(interaction, transformed_values)
           ^^^^^^^^^^^^^^^^^^^^^^^^^^^^^^^^^^^^^^^^^^^^^^^^^^^^
  File "C:\Users\PC\AppData\Roaming\Python\Python311\site-packages\discord\app_commands\commands.py", line 880, in _do_call
    raise CommandInvokeError(self, e) from e
discord.app_commands.errors.CommandInvokeError: Command '모집' raised an exception: OperationalError: no such column: discriminator

2024-03-21 12:28:01 : Command '열람' raised an exception: AttributeError: 'sqlite3.Row' object has no attribute 'display_column'
Traceback (most recent call last):
  File "C:\Users\PC\AppData\Roaming\Python\Python311\site-packages\discord\app_commands\commands.py", line 861, in _do_call
    return await self._callback(self.binding, interaction, **params)  # type: ignore
           ^^^^^^^^^^^^^^^^^^^^^^^^^^^^^^^^^^^^^^^^^^^^^^^^^^^^^^^^^
  File "C:\Users\PC\Documents\GitHub\arislena-reborn\cogs\crew.py", line 74, in lookup
    view=views.TableObjectView(
         ^^^^^^^^^^^^^^^^^^^^^^
  File "C:\Users\PC\Documents\GitHub\arislena-reborn\py_discord\views.py", line 269, in __init__
    self.add_item(button_class(tableobj, **button_class_param))
                  ^^^^^^^^^^^^^^^^^^^^^^^^^^^^^^^^^^^^^^^^^^^^
  File "C:\Users\PC\Documents\GitHub\arislena-reborn\py_discord\views.py", line 147, in __init__
    super().__init__(
  File "C:\Users\PC\Documents\GitHub\arislena-reborn\py_discord\views.py", line 67, in __init__
    display_value = getattr(table_object, table_object.display_column, "-")
                                          ^^^^^^^^^^^^^^^^^^^^^^^^^^^
AttributeError: 'sqlite3.Row' object has no attribute 'display_column'

The above exception was the direct cause of the following exception:

Traceback (most recent call last):
  File "C:\Users\PC\AppData\Roaming\Python\Python311\site-packages\discord\app_commands\tree.py", line 1242, in _call
    await command._invoke_with_namespace(interaction, namespace)
  File "C:\Users\PC\AppData\Roaming\Python\Python311\site-packages\discord\app_commands\commands.py", line 887, in _invoke_with_namespace
    return await self._do_call(interaction, transformed_values)
           ^^^^^^^^^^^^^^^^^^^^^^^^^^^^^^^^^^^^^^^^^^^^^^^^^^^^
  File "C:\Users\PC\AppData\Roaming\Python\Python311\site-packages\discord\app_commands\commands.py", line 880, in _do_call
    raise CommandInvokeError(self, e) from e
discord.app_commands.errors.CommandInvokeError: Command '열람' raised an exception: AttributeError: 'sqlite3.Row' object has no attribute 'display_column'

2024-04-04 10:16:45 : Command '열람' raised an exception: HTTPException: 400 Bad Request (error code: 50035): Invalid Form Body
In data.components.0.components.1.custom_id: Component custom id cannot be duplicated
Traceback (most recent call last):
  File "C:\Users\PC\AppData\Roaming\Python\Python311\site-packages\discord\app_commands\commands.py", line 861, in _do_call
    return await self._callback(self.binding, interaction, **params)  # type: ignore
           ^^^^^^^^^^^^^^^^^^^^^^^^^^^^^^^^^^^^^^^^^^^^^^^^^^^^^^^^^
  File "C:\Users\PC\Documents\GitHub\arislena-reborn\cogs\territory.py", line 29, in lookup
    await interaction.response.send_message(
  File "C:\Users\PC\AppData\Roaming\Python\Python311\site-packages\discord\interactions.py", line 769, in send_message
    await adapter.create_interaction_response(
  File "C:\Users\PC\AppData\Roaming\Python\Python311\site-packages\discord\webhook\async_.py", line 220, in request
    raise HTTPException(response, data)
discord.errors.HTTPException: 400 Bad Request (error code: 50035): Invalid Form Body
In data.components.0.components.1.custom_id: Component custom id cannot be duplicated

The above exception was the direct cause of the following exception:

Traceback (most recent call last):
  File "C:\Users\PC\AppData\Roaming\Python\Python311\site-packages\discord\app_commands\tree.py", line 1242, in _call
    await command._invoke_with_namespace(interaction, namespace)
  File "C:\Users\PC\AppData\Roaming\Python\Python311\site-packages\discord\app_commands\commands.py", line 887, in _invoke_with_namespace
    return await self._do_call(interaction, transformed_values)
           ^^^^^^^^^^^^^^^^^^^^^^^^^^^^^^^^^^^^^^^^^^^^^^^^^^^^
  File "C:\Users\PC\AppData\Roaming\Python\Python311\site-packages\discord\app_commands\commands.py", line 880, in _do_call
    raise CommandInvokeError(self, e) from e
discord.app_commands.errors.CommandInvokeError: Command '열람' raised an exception: HTTPException: 400 Bad Request (error code: 50035): Invalid Form Body
In data.components.0.components.1.custom_id: Component custom id cannot be duplicated

2024-04-04 10:20:42 : Command '열람' raised an exception: HTTPException: 400 Bad Request (error code: 50035): Invalid Form Body
In data.components.0.components.1.custom_id: Component custom id cannot be duplicated
Traceback (most recent call last):
  File "C:\Users\PC\AppData\Roaming\Python\Python311\site-packages\discord\app_commands\commands.py", line 861, in _do_call
    return await self._callback(self.binding, interaction, **params)  # type: ignore
           ^^^^^^^^^^^^^^^^^^^^^^^^^^^^^^^^^^^^^^^^^^^^^^^^^^^^^^^^^
  File "C:\Users\PC\Documents\GitHub\arislena-reborn\cogs\territory.py", line 29, in lookup
    await interaction.response.send_message(
  File "C:\Users\PC\AppData\Roaming\Python\Python311\site-packages\discord\interactions.py", line 769, in send_message
    await adapter.create_interaction_response(
  File "C:\Users\PC\AppData\Roaming\Python\Python311\site-packages\discord\webhook\async_.py", line 220, in request
    raise HTTPException(response, data)
discord.errors.HTTPException: 400 Bad Request (error code: 50035): Invalid Form Body
In data.components.0.components.1.custom_id: Component custom id cannot be duplicated

The above exception was the direct cause of the following exception:

Traceback (most recent call last):
  File "C:\Users\PC\AppData\Roaming\Python\Python311\site-packages\discord\app_commands\tree.py", line 1242, in _call
    await command._invoke_with_namespace(interaction, namespace)
  File "C:\Users\PC\AppData\Roaming\Python\Python311\site-packages\discord\app_commands\commands.py", line 887, in _invoke_with_namespace
    return await self._do_call(interaction, transformed_values)
           ^^^^^^^^^^^^^^^^^^^^^^^^^^^^^^^^^^^^^^^^^^^^^^^^^^^^
  File "C:\Users\PC\AppData\Roaming\Python\Python311\site-packages\discord\app_commands\commands.py", line 880, in _do_call
    raise CommandInvokeError(self, e) from e
discord.app_commands.errors.CommandInvokeError: Command '열람' raised an exception: HTTPException: 400 Bad Request (error code: 50035): Invalid Form Body
In data.components.0.components.1.custom_id: Component custom id cannot be duplicated

2024-04-04 10:27:56 : Command '열람' raised an exception: HTTPException: 400 Bad Request (error code: 50035): Invalid Form Body
In data.components.0.components.1.custom_id: Component custom id cannot be duplicated
In data.components.0.components.2.custom_id: Component custom id cannot be duplicated
Traceback (most recent call last):
  File "C:\Users\PC\AppData\Roaming\Python\Python311\site-packages\discord\app_commands\commands.py", line 861, in _do_call
    return await self._callback(self.binding, interaction, **params)  # type: ignore
           ^^^^^^^^^^^^^^^^^^^^^^^^^^^^^^^^^^^^^^^^^^^^^^^^^^^^^^^^^
  File "C:\Users\PC\Documents\GitHub\arislena-reborn\cogs\crew.py", line 72, in lookup
    await interaction.response.send_message(
  File "C:\Users\PC\AppData\Roaming\Python\Python311\site-packages\discord\interactions.py", line 769, in send_message
    await adapter.create_interaction_response(
  File "C:\Users\PC\AppData\Roaming\Python\Python311\site-packages\discord\webhook\async_.py", line 220, in request
    raise HTTPException(response, data)
discord.errors.HTTPException: 400 Bad Request (error code: 50035): Invalid Form Body
In data.components.0.components.1.custom_id: Component custom id cannot be duplicated
In data.components.0.components.2.custom_id: Component custom id cannot be duplicated

The above exception was the direct cause of the following exception:

Traceback (most recent call last):
  File "C:\Users\PC\AppData\Roaming\Python\Python311\site-packages\discord\app_commands\tree.py", line 1242, in _call
    await command._invoke_with_namespace(interaction, namespace)
  File "C:\Users\PC\AppData\Roaming\Python\Python311\site-packages\discord\app_commands\commands.py", line 887, in _invoke_with_namespace
    return await self._do_call(interaction, transformed_values)
           ^^^^^^^^^^^^^^^^^^^^^^^^^^^^^^^^^^^^^^^^^^^^^^^^^^^^
  File "C:\Users\PC\AppData\Roaming\Python\Python311\site-packages\discord\app_commands\commands.py", line 880, in _do_call
    raise CommandInvokeError(self, e) from e
discord.app_commands.errors.CommandInvokeError: Command '열람' raised an exception: HTTPException: 400 Bad Request (error code: 50035): Invalid Form Body
In data.components.0.components.1.custom_id: Component custom id cannot be duplicated
In data.components.0.components.2.custom_id: Component custom id cannot be duplicated

2024-04-04 10:41:16 : Command '열람' raised an exception: NotFound: 404 Not Found (error code: 10062): Unknown interaction
Traceback (most recent call last):
  File "C:\Users\PC\AppData\Roaming\Python\Python311\site-packages\discord\app_commands\commands.py", line 861, in _do_call
    return await self._callback(self.binding, interaction, **params)  # type: ignore
           ^^^^^^^^^^^^^^^^^^^^^^^^^^^^^^^^^^^^^^^^^^^^^^^^^^^^^^^^^
  File "C:\Users\PC\Documents\GitHub\arislena-reborn\cogs\user_management.py", line 63, in info
    await interaction.response.send_message(
  File "C:\Users\PC\AppData\Roaming\Python\Python311\site-packages\discord\interactions.py", line 769, in send_message
    await adapter.create_interaction_response(
  File "C:\Users\PC\AppData\Roaming\Python\Python311\site-packages\discord\webhook\async_.py", line 218, in request
    raise NotFound(response, data)
discord.errors.NotFound: 404 Not Found (error code: 10062): Unknown interaction

The above exception was the direct cause of the following exception:

Traceback (most recent call last):
  File "C:\Users\PC\AppData\Roaming\Python\Python311\site-packages\discord\app_commands\tree.py", line 1242, in _call
    await command._invoke_with_namespace(interaction, namespace)
  File "C:\Users\PC\AppData\Roaming\Python\Python311\site-packages\discord\app_commands\commands.py", line 887, in _invoke_with_namespace
    return await self._do_call(interaction, transformed_values)
           ^^^^^^^^^^^^^^^^^^^^^^^^^^^^^^^^^^^^^^^^^^^^^^^^^^^^
  File "C:\Users\PC\AppData\Roaming\Python\Python311\site-packages\discord\app_commands\commands.py", line 880, in _do_call
    raise CommandInvokeError(self, e) from e
discord.app_commands.errors.CommandInvokeError: Command '열람' raised an exception: NotFound: 404 Not Found (error code: 10062): Unknown interaction

2024-04-04 12:01:02 : Command '열람' raised an exception: HTTPException: 400 Bad Request (error code: 50035): Invalid Form Body
In data.components.0.components.0.label: This field is required
Traceback (most recent call last):
  File "C:\Users\PC\AppData\Roaming\Python\Python311\site-packages\discord\app_commands\commands.py", line 861, in _do_call
    return await self._callback(self.binding, interaction, **params)  # type: ignore
           ^^^^^^^^^^^^^^^^^^^^^^^^^^^^^^^^^^^^^^^^^^^^^^^^^^^^^^^^^
  File "C:\Users\PC\Documents\GitHub\arislena-reborn\cogs\user_management.py", line 63, in info
    await interaction.response.send_message(
  File "C:\Users\PC\AppData\Roaming\Python\Python311\site-packages\discord\interactions.py", line 769, in send_message
    await adapter.create_interaction_response(
  File "C:\Users\PC\AppData\Roaming\Python\Python311\site-packages\discord\webhook\async_.py", line 220, in request
    raise HTTPException(response, data)
discord.errors.HTTPException: 400 Bad Request (error code: 50035): Invalid Form Body
In data.components.0.components.0.label: This field is required

The above exception was the direct cause of the following exception:

Traceback (most recent call last):
  File "C:\Users\PC\AppData\Roaming\Python\Python311\site-packages\discord\app_commands\tree.py", line 1242, in _call
    await command._invoke_with_namespace(interaction, namespace)
  File "C:\Users\PC\AppData\Roaming\Python\Python311\site-packages\discord\app_commands\commands.py", line 887, in _invoke_with_namespace
    return await self._do_call(interaction, transformed_values)
           ^^^^^^^^^^^^^^^^^^^^^^^^^^^^^^^^^^^^^^^^^^^^^^^^^^^^
  File "C:\Users\PC\AppData\Roaming\Python\Python311\site-packages\discord\app_commands\commands.py", line 880, in _do_call
    raise CommandInvokeError(self, e) from e
discord.app_commands.errors.CommandInvokeError: Command '열람' raised an exception: HTTPException: 400 Bad Request (error code: 50035): Invalid Form Body
In data.components.0.components.0.label: This field is required

2024-04-04 16:19:09 : Command '배치' raised an exception: AttributeError: 'NoneType' object has no attribute 'id'
Traceback (most recent call last):
  File "C:\Users\PC\AppData\Roaming\Python\Python311\site-packages\discord\app_commands\commands.py", line 861, in _do_call
    return await self._callback(self.binding, interaction, **params)  # type: ignore
           ^^^^^^^^^^^^^^^^^^^^^^^^^^^^^^^^^^^^^^^^^^^^^^^^^^^^^^^^^
  File "C:\Users\PC\Documents\GitHub\arislena-reborn\cogs\crew.py", line 116, in deploy
    sample_button=views.SelectCrewToDeployButton(faction)\
                  ^^^^^^^^^^^^^^^^^^^^^^^^^^^^^^^^^^^^^^^
  File "C:\Users\PC\Documents\GitHub\arislena-reborn\py_discord\views.py", line 290, in __init__
    if self.already_deployed(): self.disabled = True
       ^^^^^^^^^^^^^^^^^^^^^^^
  File "C:\Users\PC\Documents\GitHub\arislena-reborn\py_discord\views.py", line 297, in already_deployed
    return main_db.is_exist(Deployment.__name__, crew_id = self.crew.id)
                                                           ^^^^^^^^^^^^
AttributeError: 'NoneType' object has no attribute 'id'

The above exception was the direct cause of the following exception:

Traceback (most recent call last):
  File "C:\Users\PC\AppData\Roaming\Python\Python311\site-packages\discord\app_commands\tree.py", line 1242, in _call
    await command._invoke_with_namespace(interaction, namespace)
  File "C:\Users\PC\AppData\Roaming\Python\Python311\site-packages\discord\app_commands\commands.py", line 887, in _invoke_with_namespace
    return await self._do_call(interaction, transformed_values)
           ^^^^^^^^^^^^^^^^^^^^^^^^^^^^^^^^^^^^^^^^^^^^^^^^^^^^
  File "C:\Users\PC\AppData\Roaming\Python\Python311\site-packages\discord\app_commands\commands.py", line 880, in _do_call
    raise CommandInvokeError(self, e) from e
discord.app_commands.errors.CommandInvokeError: Command '배치' raised an exception: AttributeError: 'NoneType' object has no attribute 'id'

2024-04-04 18:04:17 : Command '열람' raised an exception: TypeError: TerritoryLookupButton.__init__() missing 1 required positional argument: 'faction'
Traceback (most recent call last):
  File "C:\Users\PC\AppData\Roaming\Python\Python311\site-packages\discord\app_commands\commands.py", line 861, in _do_call
    return await self._callback(self.binding, interaction, **params)  # type: ignore
           ^^^^^^^^^^^^^^^^^^^^^^^^^^^^^^^^^^^^^^^^^^^^^^^^^^^^^^^^^
  File "C:\Users\PC\Documents\GitHub\arislena-reborn\cogs\territory.py", line 31, in lookup
    view=views.TableObjectView(
         ^^^^^^^^^^^^^^^^^^^^^^
  File "C:\Users\PC\Documents\GitHub\arislena-reborn\py_discord\views.py", line 469, in __init__
    item = sample_button.clone()\
           ^^^^^^^^^^^^^^^^^^^^^
  File "C:\Users\PC\Documents\GitHub\arislena-reborn\py_discord\views.py", line 204, in clone
    return TerritoryLookupButton()
           ^^^^^^^^^^^^^^^^^^^^^^^
TypeError: TerritoryLookupButton.__init__() missing 1 required positional argument: 'faction'

The above exception was the direct cause of the following exception:

Traceback (most recent call last):
  File "C:\Users\PC\AppData\Roaming\Python\Python311\site-packages\discord\app_commands\tree.py", line 1242, in _call
    await command._invoke_with_namespace(interaction, namespace)
  File "C:\Users\PC\AppData\Roaming\Python\Python311\site-packages\discord\app_commands\commands.py", line 887, in _invoke_with_namespace
    return await self._do_call(interaction, transformed_values)
           ^^^^^^^^^^^^^^^^^^^^^^^^^^^^^^^^^^^^^^^^^^^^^^^^^^^^
  File "C:\Users\PC\AppData\Roaming\Python\Python311\site-packages\discord\app_commands\commands.py", line 876, in _do_call
    raise CommandInvokeError(self, e) from e
discord.app_commands.errors.CommandInvokeError: Command '열람' raised an exception: TypeError: TerritoryLookupButton.__init__() missing 1 required positional argument: 'faction'

2024-04-05 11:47:15 : Command '열람' raised an exception: TypeError: Territory 클래스는 Building 클래스의 객체와만 호환됩니다.
Traceback (most recent call last):
  File "C:\Users\PC\AppData\Roaming\Python\Python311\site-packages\discord\app_commands\commands.py", line 861, in _do_call
    return await self._callback(self.binding, interaction, **params)  # type: ignore
           ^^^^^^^^^^^^^^^^^^^^^^^^^^^^^^^^^^^^^^^^^^^^^^^^^^^^^^^^^
  File "C:\Users\PC\Documents\GitHub\arislena-reborn\cogs\building.py", line 73, in view
    view=views.TableObjectView(
         ^^^^^^^^^^^^^^^^^^^^^^
  File "C:\Users\PC\Documents\GitHub\arislena-reborn\py_discord\views.py", line 490, in __init__
    .set_table_object(tableobj)\
     ^^^^^^^^^^^^^^^^^^^^^^^^^^
  File "C:\Users\PC\Documents\GitHub\arislena-reborn\py_discord\views.py", line 297, in set_table_object
    return super().set_table_object(building)
           ^^^^^^^^^^^^^^^^^^^^^^^^^^^^^^^^^^
  File "C:\Users\PC\Documents\GitHub\arislena-reborn\py_discord\views.py", line 123, in set_table_object
    self.check_type(table_object)
  File "C:\Users\PC\Documents\GitHub\arislena-reborn\py_discord\views.py", line 289, in check_type
    super().check_type(building, Building)
  File "C:\Users\PC\Documents\GitHub\arislena-reborn\py_discord\views.py", line 117, in check_type
    raise TypeError(f"{object.__class__.__name__} 클래스는 {intended_type.__name__} 클래스의 객체와만 호환됩니다.")
TypeError: Territory 클래스는 Building 클래스의 객체와만 호환됩니다.

The above exception was the direct cause of the following exception:

Traceback (most recent call last):
  File "C:\Users\PC\AppData\Roaming\Python\Python311\site-packages\discord\app_commands\tree.py", line 1242, in _call
    await command._invoke_with_namespace(interaction, namespace)
  File "C:\Users\PC\AppData\Roaming\Python\Python311\site-packages\discord\app_commands\commands.py", line 887, in _invoke_with_namespace
    return await self._do_call(interaction, transformed_values)
           ^^^^^^^^^^^^^^^^^^^^^^^^^^^^^^^^^^^^^^^^^^^^^^^^^^^^
  File "C:\Users\PC\AppData\Roaming\Python\Python311\site-packages\discord\app_commands\commands.py", line 876, in _do_call
    raise CommandInvokeError(self, e) from e
discord.app_commands.errors.CommandInvokeError: Command '열람' raised an exception: TypeError: Territory 클래스는 Building 클래스의 객체와만 호환됩니다.

2024-04-05 18:37:05 : Command '턴넘기기' raised an exception: Exception: Database is not set.
Traceback (most recent call last):
  File "C:\Users\PC\AppData\Roaming\Python\Python311\site-packages\discord\app_commands\commands.py", line 862, in _do_call
    return await self._callback(interaction, **params)  # type: ignore
           ^^^^^^^^^^^^^^^^^^^^^^^^^^^^^^^^^^^^^^^^^^^
  File "C:\Users\PC\Documents\GitHub\arislena-reborn\bot.py", line 116, in elapse_turn
    await schedule_manager.end_turn()
  File "C:\Users\PC\Documents\GitHub\arislena-reborn\py_discord\schedule_manager.py", line 126, in end_turn
    await self.execute_before_turn_end()
  File "C:\Users\PC\Documents\GitHub\arislena-reborn\py_discord\schedule_manager.py", line 223, in execute_before_turn_end
    await self.building_produce()
  File "C:\Users\PC\Documents\GitHub\arislena-reborn\py_discord\schedule_manager.py", line 175, in building_produce
    deployed_crews = building.get_deployed_crews()
                     ^^^^^^^^^^^^^^^^^^^^^^^^^^^^^
  File "C:\Users\PC\Documents\GitHub\arislena-reborn\py_system\tableobj.py", line 261, in get_deployed_crews
    self._check_database()
  File "C:\Users\PC\Documents\GitHub\arislena-reborn\py_system\abstract.py", line 122, in _check_database
    raise Exception("Database is not set.")
Exception: Database is not set.

The above exception was the direct cause of the following exception:

Traceback (most recent call last):
  File "C:\Users\PC\AppData\Roaming\Python\Python311\site-packages\discord\app_commands\tree.py", line 1242, in _call
    await command._invoke_with_namespace(interaction, namespace)
  File "C:\Users\PC\AppData\Roaming\Python\Python311\site-packages\discord\app_commands\commands.py", line 887, in _invoke_with_namespace
    return await self._do_call(interaction, transformed_values)
           ^^^^^^^^^^^^^^^^^^^^^^^^^^^^^^^^^^^^^^^^^^^^^^^^^^^^
  File "C:\Users\PC\AppData\Roaming\Python\Python311\site-packages\discord\app_commands\commands.py", line 880, in _do_call
    raise CommandInvokeError(self, e) from e
discord.app_commands.errors.CommandInvokeError: Command '턴넘기기' raised an exception: Exception: Database is not set.

2024-04-05 18:39:30 : Command '턴넘기기' raised an exception: TypeError: 'type' object does not support item assignment
Traceback (most recent call last):
  File "C:\Users\PC\AppData\Roaming\Python\Python311\site-packages\discord\app_commands\commands.py", line 862, in _do_call
    return await self._callback(interaction, **params)  # type: ignore
           ^^^^^^^^^^^^^^^^^^^^^^^^^^^^^^^^^^^^^^^^^^^
  File "C:\Users\PC\Documents\GitHub\arislena-reborn\bot.py", line 116, in elapse_turn
    await schedule_manager.end_turn()
  File "C:\Users\PC\Documents\GitHub\arislena-reborn\py_discord\schedule_manager.py", line 126, in end_turn
    await self.execute_before_turn_end()
  File "C:\Users\PC\Documents\GitHub\arislena-reborn\py_discord\schedule_manager.py", line 224, in execute_before_turn_end
    await self.building_produce()
  File "C:\Users\PC\Documents\GitHub\arislena-reborn\py_discord\schedule_manager.py", line 176, in building_produce
    deployed_crews = building.get_deployed_crews()
                     ^^^^^^^^^^^^^^^^^^^^^^^^^^^^^
  File "C:\Users\PC\Documents\GitHub\arislena-reborn\py_system\tableobj.py", line 266, in get_deployed_crews
    deployments = list[Deployment] = [Deployment.from_data(data) for data in self._database.fetch_many("deployment", building_id=self.id)]
                  ~~~~^^^^^^^^^^^^
TypeError: 'type' object does not support item assignment

The above exception was the direct cause of the following exception:

Traceback (most recent call last):
  File "C:\Users\PC\AppData\Roaming\Python\Python311\site-packages\discord\app_commands\tree.py", line 1242, in _call
    await command._invoke_with_namespace(interaction, namespace)
  File "C:\Users\PC\AppData\Roaming\Python\Python311\site-packages\discord\app_commands\commands.py", line 887, in _invoke_with_namespace
    return await self._do_call(interaction, transformed_values)
           ^^^^^^^^^^^^^^^^^^^^^^^^^^^^^^^^^^^^^^^^^^^^^^^^^^^^
  File "C:\Users\PC\AppData\Roaming\Python\Python311\site-packages\discord\app_commands\commands.py", line 876, in _do_call
    raise CommandInvokeError(self, e) from e
discord.app_commands.errors.CommandInvokeError: Command '턴넘기기' raised an exception: TypeError: 'type' object does not support item assignment

2024-04-05 18:40:17 : Command '턴넘기기' raised an exception: TypeError: BasicBuilding.__init__() got an unexpected keyword argument 'category'
Traceback (most recent call last):
  File "C:\Users\PC\AppData\Roaming\Python\Python311\site-packages\discord\app_commands\commands.py", line 862, in _do_call
    return await self._callback(interaction, **params)  # type: ignore
           ^^^^^^^^^^^^^^^^^^^^^^^^^^^^^^^^^^^^^^^^^^^
  File "C:\Users\PC\Documents\GitHub\arislena-reborn\bot.py", line 116, in elapse_turn
    await schedule_manager.end_turn()
  File "C:\Users\PC\Documents\GitHub\arislena-reborn\py_discord\schedule_manager.py", line 126, in end_turn
    await self.execute_before_turn_end()
  File "C:\Users\PC\Documents\GitHub\arislena-reborn\py_discord\schedule_manager.py", line 224, in execute_before_turn_end
    await self.building_produce()
  File "C:\Users\PC\Documents\GitHub\arislena-reborn\py_discord\schedule_manager.py", line 180, in building_produce
    sys_building = systemobj.BuildingBase.from_building(building)
                   ^^^^^^^^^^^^^^^^^^^^^^^^^^^^^^^^^^^^^^^^^^^^^^
  File "C:\Users\PC\Documents\GitHub\arislena-reborn\py_system\systemobj.py", line 74, in from_building
    return t(**building.get_dict())
           ^^^^^^^^^^^^^^^^^^^^^^^^
TypeError: BasicBuilding.__init__() got an unexpected keyword argument 'category'

The above exception was the direct cause of the following exception:

Traceback (most recent call last):
  File "C:\Users\PC\AppData\Roaming\Python\Python311\site-packages\discord\app_commands\tree.py", line 1242, in _call
    await command._invoke_with_namespace(interaction, namespace)
  File "C:\Users\PC\AppData\Roaming\Python\Python311\site-packages\discord\app_commands\commands.py", line 887, in _invoke_with_namespace
    return await self._do_call(interaction, transformed_values)
           ^^^^^^^^^^^^^^^^^^^^^^^^^^^^^^^^^^^^^^^^^^^^^^^^^^^^
  File "C:\Users\PC\AppData\Roaming\Python\Python311\site-packages\discord\app_commands\commands.py", line 876, in _do_call
    raise CommandInvokeError(self, e) from e
discord.app_commands.errors.CommandInvokeError: Command '턴넘기기' raised an exception: TypeError: BasicBuilding.__init__() got an unexpected keyword argument 'category'

2024-04-05 23:17:51 : Command '턴넘기기' raised an exception: TypeError: exceptions must derive from BaseException
Traceback (most recent call last):
  File "C:\Users\PC\AppData\Roaming\Python\Python311\site-packages\discord\app_commands\commands.py", line 862, in _do_call
    return await self._callback(interaction, **params)  # type: ignore
           ^^^^^^^^^^^^^^^^^^^^^^^^^^^^^^^^^^^^^^^^^^^
  File "C:\Users\PC\Documents\GitHub\arislena-reborn\bot.py", line 116, in elapse_turn
    await schedule_manager.end_turn()
  File "C:\Users\PC\Documents\GitHub\arislena-reborn\py_discord\schedule_manager.py", line 126, in end_turn
    await self.execute_before_turn_end()
  File "C:\Users\PC\Documents\GitHub\arislena-reborn\py_discord\schedule_manager.py", line 224, in execute_before_turn_end
    await self.building_produce()
  File "C:\Users\PC\Documents\GitHub\arislena-reborn\py_discord\schedule_manager.py", line 181, in building_produce
    production_recipe = sys_building.produce()
                        ^^^^^^^^^^^^^^^^^^^^^^
  File "C:\Users\PC\Documents\GitHub\arislena-reborn\py_system\systemobj.py", line 93, in produce
    super().produce()
  File "C:\Users\PC\Documents\GitHub\arislena-reborn\py_system\systemobj.py", line 69, in produce
    raise ProductionRecipe()
TypeError: exceptions must derive from BaseException

The above exception was the direct cause of the following exception:

Traceback (most recent call last):
  File "C:\Users\PC\AppData\Roaming\Python\Python311\site-packages\discord\app_commands\tree.py", line 1242, in _call
    await command._invoke_with_namespace(interaction, namespace)
  File "C:\Users\PC\AppData\Roaming\Python\Python311\site-packages\discord\app_commands\commands.py", line 887, in _invoke_with_namespace
    return await self._do_call(interaction, transformed_values)
           ^^^^^^^^^^^^^^^^^^^^^^^^^^^^^^^^^^^^^^^^^^^^^^^^^^^^
  File "C:\Users\PC\AppData\Roaming\Python\Python311\site-packages\discord\app_commands\commands.py", line 876, in _do_call
    raise CommandInvokeError(self, e) from e
discord.app_commands.errors.CommandInvokeError: Command '턴넘기기' raised an exception: TypeError: exceptions must derive from BaseException

2024-04-05 23:19:39 : Command '턴넘기기' raised an exception: AttributeError: 'NoneType' object has no attribute 'consume'
Traceback (most recent call last):
  File "C:\Users\PC\AppData\Roaming\Python\Python311\site-packages\discord\app_commands\commands.py", line 862, in _do_call
    return await self._callback(interaction, **params)  # type: ignore
           ^^^^^^^^^^^^^^^^^^^^^^^^^^^^^^^^^^^^^^^^^^^
  File "C:\Users\PC\Documents\GitHub\arislena-reborn\bot.py", line 116, in elapse_turn
    await schedule_manager.end_turn()
  File "C:\Users\PC\Documents\GitHub\arislena-reborn\py_discord\schedule_manager.py", line 126, in end_turn
    await self.execute_before_turn_end()
  File "C:\Users\PC\Documents\GitHub\arislena-reborn\py_discord\schedule_manager.py", line 224, in execute_before_turn_end
    await self.building_produce()
  File "C:\Users\PC\Documents\GitHub\arislena-reborn\py_discord\schedule_manager.py", line 186, in building_produce
    for consume_resource in production_recipe.consume:
                            ^^^^^^^^^^^^^^^^^^^^^^^^^
AttributeError: 'NoneType' object has no attribute 'consume'

The above exception was the direct cause of the following exception:

Traceback (most recent call last):
  File "C:\Users\PC\AppData\Roaming\Python\Python311\site-packages\discord\app_commands\tree.py", line 1242, in _call
    await command._invoke_with_namespace(interaction, namespace)
  File "C:\Users\PC\AppData\Roaming\Python\Python311\site-packages\discord\app_commands\commands.py", line 887, in _invoke_with_namespace
    return await self._do_call(interaction, transformed_values)
           ^^^^^^^^^^^^^^^^^^^^^^^^^^^^^^^^^^^^^^^^^^^^^^^^^^^^
  File "C:\Users\PC\AppData\Roaming\Python\Python311\site-packages\discord\app_commands\commands.py", line 880, in _do_call
    raise CommandInvokeError(self, e) from e
discord.app_commands.errors.CommandInvokeError: Command '턴넘기기' raised an exception: AttributeError: 'NoneType' object has no attribute 'consume'

2024-04-05 23:23:40 : Command '턴넘기기' raised an exception: TypeError: BotBase.announce() missing 1 required positional argument: 'guild_id'
Traceback (most recent call last):
  File "C:\Users\PC\AppData\Roaming\Python\Python311\site-packages\discord\app_commands\commands.py", line 862, in _do_call
    return await self._callback(interaction, **params)  # type: ignore
           ^^^^^^^^^^^^^^^^^^^^^^^^^^^^^^^^^^^^^^^^^^^
  File "C:\Users\PC\Documents\GitHub\arislena-reborn\bot.py", line 116, in elapse_turn
    await schedule_manager.end_turn()
  File "C:\Users\PC\Documents\GitHub\arislena-reborn\py_discord\schedule_manager.py", line 132, in end_turn
    await self.execute_after_turn_end()
  File "C:\Users\PC\Documents\GitHub\arislena-reborn\py_discord\schedule_manager.py", line 240, in execute_after_turn_end
    await self.bot.announce(f"{ari_enum.Availability.UNAVAILABLE.express()} 상태인 모든 대원과 가축이 {ari_enum.Availability.STANDBY.express()} 상태로 변경되었습니다.")
          ^^^^^^^^^^^^^^^^^^^^^^^^^^^^^^^^^^^^^^^^^^^^^^^^^^^^^^^^^^^^^^^^^^^^^^^^^^^^^^^^^^^^^^^^^^^^^^^^^^^^^^^^^^^^^^^^^^^^^^^^^^^^^^^^^^^^^^^^^^^^^^^^^^^^^^^^^^^^^^
TypeError: BotBase.announce() missing 1 required positional argument: 'guild_id'

The above exception was the direct cause of the following exception:

Traceback (most recent call last):
  File "C:\Users\PC\AppData\Roaming\Python\Python311\site-packages\discord\app_commands\tree.py", line 1242, in _call
    await command._invoke_with_namespace(interaction, namespace)
  File "C:\Users\PC\AppData\Roaming\Python\Python311\site-packages\discord\app_commands\commands.py", line 887, in _invoke_with_namespace
    return await self._do_call(interaction, transformed_values)
           ^^^^^^^^^^^^^^^^^^^^^^^^^^^^^^^^^^^^^^^^^^^^^^^^^^^^
  File "C:\Users\PC\AppData\Roaming\Python\Python311\site-packages\discord\app_commands\commands.py", line 876, in _do_call
    raise CommandInvokeError(self, e) from e
discord.app_commands.errors.CommandInvokeError: Command '턴넘기기' raised an exception: TypeError: BotBase.announce() missing 1 required positional argument: 'guild_id'

2024-04-05 23:54:23 : Command '턴넘기기' raised an exception: TypeError: BotBase.announce() missing 1 required positional argument: 'guild_id'
Traceback (most recent call last):
  File "C:\Users\PC\AppData\Roaming\Python\Python311\site-packages\discord\app_commands\commands.py", line 862, in _do_call
    return await self._callback(interaction, **params)  # type: ignore
           ^^^^^^^^^^^^^^^^^^^^^^^^^^^^^^^^^^^^^^^^^^^
  File "C:\Users\PC\Documents\GitHub\arislena-reborn\bot.py", line 116, in elapse_turn
    await schedule_manager.end_turn()
  File "C:\Users\PC\Documents\GitHub\arislena-reborn\py_discord\schedule_manager.py", line 118, in end_turn
    self.bot.announce(
TypeError: BotBase.announce() missing 1 required positional argument: 'guild_id'

The above exception was the direct cause of the following exception:

Traceback (most recent call last):
  File "C:\Users\PC\AppData\Roaming\Python\Python311\site-packages\discord\app_commands\tree.py", line 1242, in _call
    await command._invoke_with_namespace(interaction, namespace)
  File "C:\Users\PC\AppData\Roaming\Python\Python311\site-packages\discord\app_commands\commands.py", line 887, in _invoke_with_namespace
    return await self._do_call(interaction, transformed_values)
           ^^^^^^^^^^^^^^^^^^^^^^^^^^^^^^^^^^^^^^^^^^^^^^^^^^^^
  File "C:\Users\PC\AppData\Roaming\Python\Python311\site-packages\discord\app_commands\commands.py", line 876, in _do_call
    raise CommandInvokeError(self, e) from e
discord.app_commands.errors.CommandInvokeError: Command '턴넘기기' raised an exception: TypeError: BotBase.announce() missing 1 required positional argument: 'guild_id'

2024-04-08 16:59:38 : Command '턴넘기기' raised an exception: AttributeError: 'list' object has no attribute '__name__'
Traceback (most recent call last):
  File "C:\Users\PC\AppData\Roaming\Python\Python311\site-packages\discord\app_commands\commands.py", line 862, in _do_call
    return await self._callback(interaction, **params)  # type: ignore
           ^^^^^^^^^^^^^^^^^^^^^^^^^^^^^^^^^^^^^^^^^^^
  File "C:\Users\PC\Documents\GitHub\arislena-reborn\bot.py", line 118, in elapse_turn
    await schedule_manager.end_turn()
  File "C:\Users\PC\Documents\GitHub\arislena-reborn\py_discord\schedule_manager.py", line 140, in end_turn
    await self.execute_after_turn_end()
  File "C:\Users\PC\Documents\GitHub\arislena-reborn\py_discord\schedule_manager.py", line 282, in execute_after_turn_end
    for row in self.main_db.fetch_many(table.__name__, availability=ari_enum.Availability.UNAVAILABLE.value):
                                       ^^^^^^^^^^^^^^
AttributeError: 'list' object has no attribute '__name__'

The above exception was the direct cause of the following exception:

Traceback (most recent call last):
  File "C:\Users\PC\AppData\Roaming\Python\Python311\site-packages\discord\app_commands\tree.py", line 1242, in _call
    await command._invoke_with_namespace(interaction, namespace)
  File "C:\Users\PC\AppData\Roaming\Python\Python311\site-packages\discord\app_commands\commands.py", line 887, in _invoke_with_namespace
    return await self._do_call(interaction, transformed_values)
           ^^^^^^^^^^^^^^^^^^^^^^^^^^^^^^^^^^^^^^^^^^^^^^^^^^^^
  File "C:\Users\PC\AppData\Roaming\Python\Python311\site-packages\discord\app_commands\commands.py", line 880, in _do_call
    raise CommandInvokeError(self, e) from e
discord.app_commands.errors.CommandInvokeError: Command '턴넘기기' raised an exception: AttributeError: 'list' object has no attribute '__name__'

2024-04-12 10:53:40 : Command '목록' raised an exception: AttributeError: 'list' object has no attribute 'keys'
Traceback (most recent call last):
  File "C:\Users\PC\AppData\Roaming\Python\Python311\site-packages\discord\app_commands\commands.py", line 861, in _do_call
    return await self._callback(self.binding, interaction, **params)  # type: ignore
           ^^^^^^^^^^^^^^^^^^^^^^^^^^^^^^^^^^^^^^^^^^^^^^^^^^^^^^^^^
  File "C:\Users\PC\Documents\GitHub\arislena-reborn\cogs\dice_package.py", line 125, in show_dice_list
    for number, dice_name in enumerate(registered_dice_list.keys(), start=1):
                                       ^^^^^^^^^^^^^^^^^^^^^^^^^
AttributeError: 'list' object has no attribute 'keys'

The above exception was the direct cause of the following exception:

Traceback (most recent call last):
  File "C:\Users\PC\AppData\Roaming\Python\Python311\site-packages\discord\app_commands\tree.py", line 1242, in _call
    await command._invoke_with_namespace(interaction, namespace)
  File "C:\Users\PC\AppData\Roaming\Python\Python311\site-packages\discord\app_commands\commands.py", line 887, in _invoke_with_namespace
    return await self._do_call(interaction, transformed_values)
           ^^^^^^^^^^^^^^^^^^^^^^^^^^^^^^^^^^^^^^^^^^^^^^^^^^^^
  File "C:\Users\PC\AppData\Roaming\Python\Python311\site-packages\discord\app_commands\commands.py", line 880, in _do_call
    raise CommandInvokeError(self, e) from e
discord.app_commands.errors.CommandInvokeError: Command '목록' raised an exception: AttributeError: 'list' object has no attribute 'keys'

2024-04-12 11:06:36 : Command '목록' raised an exception: AttributeError: 'list' object has no attribute 'keys'
Traceback (most recent call last):
  File "C:\Users\PC\AppData\Roaming\Python\Python311\site-packages\discord\app_commands\commands.py", line 861, in _do_call
    return await self._callback(self.binding, interaction, **params)  # type: ignore
           ^^^^^^^^^^^^^^^^^^^^^^^^^^^^^^^^^^^^^^^^^^^^^^^^^^^^^^^^^
  File "C:\Users\PC\Documents\GitHub\arislena-reborn\cogs\dice_package.py", line 125, in show_dice_list
    for number, dice_name in enumerate(registered_dice_list.keys(), start=1):
                                       ^^^^^^^^^^^^^^^^^^^^^^^^^
AttributeError: 'list' object has no attribute 'keys'

The above exception was the direct cause of the following exception:

Traceback (most recent call last):
  File "C:\Users\PC\AppData\Roaming\Python\Python311\site-packages\discord\app_commands\tree.py", line 1242, in _call
    await command._invoke_with_namespace(interaction, namespace)
  File "C:\Users\PC\AppData\Roaming\Python\Python311\site-packages\discord\app_commands\commands.py", line 887, in _invoke_with_namespace
    return await self._do_call(interaction, transformed_values)
           ^^^^^^^^^^^^^^^^^^^^^^^^^^^^^^^^^^^^^^^^^^^^^^^^^^^^
  File "C:\Users\PC\AppData\Roaming\Python\Python311\site-packages\discord\app_commands\commands.py", line 880, in _do_call
    raise CommandInvokeError(self, e) from e
discord.app_commands.errors.CommandInvokeError: Command '목록' raised an exception: AttributeError: 'list' object has no attribute 'keys'

