2023-09-22 00:08:46 : Command '버튼' raised an exception: HTTPException: 400 Bad Request (error code: 50035): Invalid Form Body
In data.components.0.components.0.emoji.id: Invalid emoji
Traceback (most recent call last):
  File "C:\Users\ghftr\AppData\Roaming\Python\Python311\site-packages\discord\app_commands\commands.py", line 861, in _do_call
    return await self._callback(self.binding, interaction, **params)  # type: ignore
           ^^^^^^^^^^^^^^^^^^^^^^^^^^^^^^^^^^^^^^^^^^^^^^^^^^^^^^^^^
  File "C:\Users\ghftr\Documents\GitHub\arislena-reborn\arislena-reborn\cogs\test.py", line 18, in test
    await interaction.response.send_message("버튼을 눌러봐!", view=button_interaction.test_button())
  File "C:\Users\ghftr\AppData\Roaming\Python\Python311\site-packages\discord\interactions.py", line 769, in send_message
    await adapter.create_interaction_response(
  File "C:\Users\ghftr\AppData\Roaming\Python\Python311\site-packages\discord\webhook\async_.py", line 220, in request
    raise HTTPException(response, data)
discord.errors.HTTPException: 400 Bad Request (error code: 50035): Invalid Form Body
In data.components.0.components.0.emoji.id: Invalid emoji

The above exception was the direct cause of the following exception:

Traceback (most recent call last):
  File "C:\Users\ghftr\AppData\Roaming\Python\Python311\site-packages\discord\app_commands\tree.py", line 1242, in _call
    await command._invoke_with_namespace(interaction, namespace)
  File "C:\Users\ghftr\AppData\Roaming\Python\Python311\site-packages\discord\app_commands\commands.py", line 887, in _invoke_with_namespace
    return await self._do_call(interaction, transformed_values)
           ^^^^^^^^^^^^^^^^^^^^^^^^^^^^^^^^^^^^^^^^^^^^^^^^^^^^
  File "C:\Users\ghftr\AppData\Roaming\Python\Python311\site-packages\discord\app_commands\commands.py", line 880, in _do_call
    raise CommandInvokeError(self, e) from e
discord.app_commands.errors.CommandInvokeError: Command '버튼' raised an exception: HTTPException: 400 Bad Request (error code: 50035): Invalid Form Body
In data.components.0.components.0.emoji.id: Invalid emoji

2023-09-22 17:19:21 : Command '등록신청' raised an exception: AttributeError: module 'py.database' has no attribute 'User'
Traceback (most recent call last):
  File "C:\Users\ghftr\AppData\Roaming\Python\Python311\site-packages\discord\app_commands\commands.py", line 861, in _do_call
    return await self._callback(self.binding, interaction, **params)  # type: ignore
           ^^^^^^^^^^^^^^^^^^^^^^^^^^^^^^^^^^^^^^^^^^^^^^^^^^^^^^^^^
  File "C:\Users\ghftr\Documents\GitHub\arislena-reborn\arislena-reborn\cogs\user_management.py", line 27, in register
    user:tableobj.User = db.fetch("user", f"discord_id = {interaction.user.id}")
                         ^^^^^^^^^^^^^^^^^^^^^^^^^^^^^^^^^^^^^^^^^^^^^^^^^^^^^^^
  File "C:\Users\ghftr\Documents\GitHub\arislena-reborn\arislena-reborn\py\database.py", line 40, in fetch
    return getattr(sys.modules[__name__], table.capitalize())(*data)
           ^^^^^^^^^^^^^^^^^^^^^^^^^^^^^^^^^^^^^^^^^^^^^^^^^^
AttributeError: module 'py.database' has no attribute 'User'

The above exception was the direct cause of the following exception:

Traceback (most recent call last):
  File "C:\Users\ghftr\AppData\Roaming\Python\Python311\site-packages\discord\app_commands\tree.py", line 1242, in _call
    await command._invoke_with_namespace(interaction, namespace)
  File "C:\Users\ghftr\AppData\Roaming\Python\Python311\site-packages\discord\app_commands\commands.py", line 887, in _invoke_with_namespace
    return await self._do_call(interaction, transformed_values)
           ^^^^^^^^^^^^^^^^^^^^^^^^^^^^^^^^^^^^^^^^^^^^^^^^^^^^
  File "C:\Users\ghftr\AppData\Roaming\Python\Python311\site-packages\discord\app_commands\commands.py", line 880, in _do_call
    raise CommandInvokeError(self, e) from e
discord.app_commands.errors.CommandInvokeError: Command '등록신청' raised an exception: AttributeError: module 'py.database' has no attribute 'User'

2023-09-22 18:01:31 : Command '등록' raised an exception: TypeError: Expected discord.Colour, int, or None but received Color instead.
Traceback (most recent call last):
  File "C:\Users\ghftr\AppData\Roaming\Python\Python311\site-packages\discord\app_commands\commands.py", line 861, in _do_call
    return await self._callback(self.binding, interaction, **params)  # type: ignore
           ^^^^^^^^^^^^^^^^^^^^^^^^^^^^^^^^^^^^^^^^^^^^^^^^^^^^^^^^^
  File "C:\Users\ghftr\Documents\GitHub\arislena-reborn\arislena-reborn\cogs\user_management.py", line 37, in register
    embed = discord.Embed(title=embed_title, description=embed_description, color=embed_color)
            ^^^^^^^^^^^^^^^^^^^^^^^^^^^^^^^^^^^^^^^^^^^^^^^^^^^^^^^^^^^^^^^^^^^^^^^^^^^^^^^^^^
  File "C:\Users\ghftr\AppData\Roaming\Python\Python311\site-packages\discord\embeds.py", line 179, in __init__
    self.colour = colour if colour is not None else color
    ^^^^^^^^^^^
  File "C:\Users\ghftr\AppData\Roaming\Python\Python311\site-packages\discord\embeds.py", line 323, in colour
    raise TypeError(f'Expected discord.Colour, int, or None but received {value.__class__.__name__} instead.')
TypeError: Expected discord.Colour, int, or None but received Color instead.

The above exception was the direct cause of the following exception:

Traceback (most recent call last):
  File "C:\Users\ghftr\AppData\Roaming\Python\Python311\site-packages\discord\app_commands\tree.py", line 1242, in _call
    await command._invoke_with_namespace(interaction, namespace)
  File "C:\Users\ghftr\AppData\Roaming\Python\Python311\site-packages\discord\app_commands\commands.py", line 887, in _invoke_with_namespace
    return await self._do_call(interaction, transformed_values)
           ^^^^^^^^^^^^^^^^^^^^^^^^^^^^^^^^^^^^^^^^^^^^^^^^^^^^
  File "C:\Users\ghftr\AppData\Roaming\Python\Python311\site-packages\discord\app_commands\commands.py", line 876, in _do_call
    raise CommandInvokeError(self, e) from e
discord.app_commands.errors.CommandInvokeError: Command '등록' raised an exception: TypeError: Expected discord.Colour, int, or None but received Color instead.

2023-09-25 17:54:56 : Command '등록' raised an exception: OperationalError: no such column: None
Traceback (most recent call last):
  File "C:\Users\ghftr\AppData\Roaming\Python\Python311\site-packages\discord\app_commands\commands.py", line 861, in _do_call
    return await self._callback(self.binding, interaction, **params)  # type: ignore
           ^^^^^^^^^^^^^^^^^^^^^^^^^^^^^^^^^^^^^^^^^^^^^^^^^^^^^^^^^
  File "C:\Users\ghftr\Documents\GitHub\arislena-reborn\arislena-reborn\cogs\user_management.py", line 33, in register
    db.insert(user)
  File "C:\Users\ghftr\Documents\GitHub\arislena-reborn\arislena-reborn\py\database.py", line 142, in insert
    self.cursor.execute(sql)
sqlite3.OperationalError: no such column: None

The above exception was the direct cause of the following exception:

Traceback (most recent call last):
  File "C:\Users\ghftr\AppData\Roaming\Python\Python311\site-packages\discord\app_commands\tree.py", line 1242, in _call
    await command._invoke_with_namespace(interaction, namespace)
  File "C:\Users\ghftr\AppData\Roaming\Python\Python311\site-packages\discord\app_commands\commands.py", line 887, in _invoke_with_namespace
    return await self._do_call(interaction, transformed_values)
           ^^^^^^^^^^^^^^^^^^^^^^^^^^^^^^^^^^^^^^^^^^^^^^^^^^^^
  File "C:\Users\ghftr\AppData\Roaming\Python\Python311\site-packages\discord\app_commands\commands.py", line 880, in _do_call
    raise CommandInvokeError(self, e) from e
discord.app_commands.errors.CommandInvokeError: Command '등록' raised an exception: OperationalError: no such column: None

2023-10-15 21:12:38 : Command '목록' raised an exception: AttributeError: type object 'DiceMemory' has no attribute 'content'
Traceback (most recent call last):
  File "C:\Users\ghftr\AppData\Roaming\Python\Python311\site-packages\discord\app_commands\commands.py", line 861, in _do_call
    return await self._callback(self.binding, interaction, **params)  # type: ignore
           ^^^^^^^^^^^^^^^^^^^^^^^^^^^^^^^^^^^^^^^^^^^^^^^^^^^^^^^^^
  File "C:\Users\ghftr\Documents\GitHub\arislena-reborn\arislena-reborn\cogs\dice_package.py", line 112, in show_dice_list
    registered_dice_list = jsonobj.DiceMemory.content
                           ^^^^^^^^^^^^^^^^^^^^^^^^^^
AttributeError: type object 'DiceMemory' has no attribute 'content'

The above exception was the direct cause of the following exception:

Traceback (most recent call last):
  File "C:\Users\ghftr\AppData\Roaming\Python\Python311\site-packages\discord\app_commands\tree.py", line 1242, in _call
    await command._invoke_with_namespace(interaction, namespace)
  File "C:\Users\ghftr\AppData\Roaming\Python\Python311\site-packages\discord\app_commands\commands.py", line 887, in _invoke_with_namespace
    return await self._do_call(interaction, transformed_values)
           ^^^^^^^^^^^^^^^^^^^^^^^^^^^^^^^^^^^^^^^^^^^^^^^^^^^^
  File "C:\Users\ghftr\AppData\Roaming\Python\Python311\site-packages\discord\app_commands\commands.py", line 880, in _do_call
    raise CommandInvokeError(self, e) from e
discord.app_commands.errors.CommandInvokeError: Command '목록' raised an exception: AttributeError: type object 'DiceMemory' has no attribute 'content'

2023-10-22 22:24:12 : Command '등록' raised an exception: OperationalError: no such column: None
Traceback (most recent call last):
  File "C:\Users\정진혁\AppData\Roaming\Python\Python311\site-packages\discord\app_commands\commands.py", line 827, in _do_call
    return await self._callback(self.binding, interaction, **params)  # type: ignore
           ^^^^^^^^^^^^^^^^^^^^^^^^^^^^^^^^^^^^^^^^^^^^^^^^^^^^^^^^^
  File "C:\Users\정진혁\OneDrive - Ars Praxia\Documents\GitHub\arislena-reborn\cogs\user_management.py", line 33, in register
    main_db.insert(tableobj.User_setting(user_ID=user.ID))
  File "C:\Users\정진혁\OneDrive - Ars Praxia\Documents\GitHub\arislena-reborn\py_system\database.py", line 144, in insert
    self.cursor.execute(sql)
sqlite3.OperationalError: no such column: None

The above exception was the direct cause of the following exception:

Traceback (most recent call last):
  File "C:\Users\정진혁\AppData\Roaming\Python\Python311\site-packages\discord\app_commands\tree.py", line 1248, in _call
    await command._invoke_with_namespace(interaction, namespace)
  File "C:\Users\정진혁\AppData\Roaming\Python\Python311\site-packages\discord\app_commands\commands.py", line 853, in _invoke_with_namespace
    return await self._do_call(interaction, transformed_values)
           ^^^^^^^^^^^^^^^^^^^^^^^^^^^^^^^^^^^^^^^^^^^^^^^^^^^^
  File "C:\Users\정진혁\AppData\Roaming\Python\Python311\site-packages\discord\app_commands\commands.py", line 846, in _do_call
    raise CommandInvokeError(self, e) from e
discord.app_commands.errors.CommandInvokeError: Command '등록' raised an exception: OperationalError: no such column: None

2023-10-22 22:26:06 : Command '등록' raised an exception: OperationalError: no such column: None
Traceback (most recent call last):
  File "C:\Users\정진혁\AppData\Roaming\Python\Python311\site-packages\discord\app_commands\commands.py", line 827, in _do_call
    return await self._callback(self.binding, interaction, **params)  # type: ignore
           ^^^^^^^^^^^^^^^^^^^^^^^^^^^^^^^^^^^^^^^^^^^^^^^^^^^^^^^^^
  File "C:\Users\정진혁\OneDrive - Ars Praxia\Documents\GitHub\arislena-reborn\cogs\user_management.py", line 33, in register
    main_db.insert(tableobj.User_setting(user_ID=user.ID))
  File "C:\Users\정진혁\OneDrive - Ars Praxia\Documents\GitHub\arislena-reborn\py_system\database.py", line 144, in insert
    self.cursor.execute(sql)
sqlite3.OperationalError: no such column: None

The above exception was the direct cause of the following exception:

Traceback (most recent call last):
  File "C:\Users\정진혁\AppData\Roaming\Python\Python311\site-packages\discord\app_commands\tree.py", line 1248, in _call
    await command._invoke_with_namespace(interaction, namespace)
  File "C:\Users\정진혁\AppData\Roaming\Python\Python311\site-packages\discord\app_commands\commands.py", line 853, in _invoke_with_namespace
    return await self._do_call(interaction, transformed_values)
           ^^^^^^^^^^^^^^^^^^^^^^^^^^^^^^^^^^^^^^^^^^^^^^^^^^^^
  File "C:\Users\정진혁\AppData\Roaming\Python\Python311\site-packages\discord\app_commands\commands.py", line 846, in _do_call
    raise CommandInvokeError(self, e) from e
discord.app_commands.errors.CommandInvokeError: Command '등록' raised an exception: OperationalError: no such column: None

2023-10-22 22:33:29 : Command '등록' raised an exception: TypeError: User_setting.__init__() got an unexpected keyword argument 'user_ID'
Traceback (most recent call last):
  File "C:\Users\정진혁\AppData\Roaming\Python\Python311\site-packages\discord\app_commands\commands.py", line 827, in _do_call
    return await self._callback(self.binding, interaction, **params)  # type: ignore
           ^^^^^^^^^^^^^^^^^^^^^^^^^^^^^^^^^^^^^^^^^^^^^^^^^^^^^^^^^
  File "C:\Users\정진혁\OneDrive - Ars Praxia\Documents\GitHub\arislena-reborn\cogs\user_management.py", line 32, in register
    user_settings = tableobj.User_setting(user_ID=interaction.user.id)
                    ^^^^^^^^^^^^^^^^^^^^^^^^^^^^^^^^^^^^^^^^^^^^^^^^^^
TypeError: User_setting.__init__() got an unexpected keyword argument 'user_ID'

The above exception was the direct cause of the following exception:

Traceback (most recent call last):
  File "C:\Users\정진혁\AppData\Roaming\Python\Python311\site-packages\discord\app_commands\tree.py", line 1248, in _call
    await command._invoke_with_namespace(interaction, namespace)
  File "C:\Users\정진혁\AppData\Roaming\Python\Python311\site-packages\discord\app_commands\commands.py", line 853, in _invoke_with_namespace
    return await self._do_call(interaction, transformed_values)
           ^^^^^^^^^^^^^^^^^^^^^^^^^^^^^^^^^^^^^^^^^^^^^^^^^^^^
  File "C:\Users\정진혁\AppData\Roaming\Python\Python311\site-packages\discord\app_commands\commands.py", line 842, in _do_call
    raise CommandInvokeError(self, e) from e
discord.app_commands.errors.CommandInvokeError: Command '등록' raised an exception: TypeError: User_setting.__init__() got an unexpected keyword argument 'user_ID'

2023-10-22 22:47:40 : Command '설정' raised an exception: TypeError: convert_to_tableobj() takes 2 positional arguments but 5 were given
Traceback (most recent call last):
  File "C:\Users\정진혁\AppData\Roaming\Python\Python311\site-packages\discord\app_commands\commands.py", line 827, in _do_call
    return await self._callback(self.binding, interaction, **params)  # type: ignore
           ^^^^^^^^^^^^^^^^^^^^^^^^^^^^^^^^^^^^^^^^^^^^^^^^^^^^^^^^^
  File "C:\Users\정진혁\OneDrive - Ars Praxia\Documents\GitHub\arislena-reborn\cogs\user_management.py", line 59, in setting
    user:tableobj.User = main_db.fetch("user", f"discord_id = {interaction.user.id}")
                         ^^^^^^^^^^^^^^^^^^^^^^^^^^^^^^^^^^^^^^^^^^^^^^^^^^^^^^^^^^^^
  File "C:\Users\정진혁\OneDrive - Ars Praxia\Documents\GitHub\arislena-reborn\py_system\database.py", line 41, in fetch
    return tableobj.convert_to_tableobj(table, *data)
           ^^^^^^^^^^^^^^^^^^^^^^^^^^^^^^^^^^^^^^^^^^
TypeError: convert_to_tableobj() takes 2 positional arguments but 5 were given

The above exception was the direct cause of the following exception:

Traceback (most recent call last):
  File "C:\Users\정진혁\AppData\Roaming\Python\Python311\site-packages\discord\app_commands\tree.py", line 1248, in _call
    await command._invoke_with_namespace(interaction, namespace)
  File "C:\Users\정진혁\AppData\Roaming\Python\Python311\site-packages\discord\app_commands\commands.py", line 853, in _invoke_with_namespace
    return await self._do_call(interaction, transformed_values)
           ^^^^^^^^^^^^^^^^^^^^^^^^^^^^^^^^^^^^^^^^^^^^^^^^^^^^
  File "C:\Users\정진혁\AppData\Roaming\Python\Python311\site-packages\discord\app_commands\commands.py", line 842, in _do_call
    raise CommandInvokeError(self, e) from e
discord.app_commands.errors.CommandInvokeError: Command '설정' raised an exception: TypeError: convert_to_tableobj() takes 2 positional arguments but 5 were given

2023-10-22 22:49:38 : Command '설정' raised an exception: OperationalError: no such column: user_ID
Traceback (most recent call last):
  File "C:\Users\정진혁\AppData\Roaming\Python\Python311\site-packages\discord\app_commands\commands.py", line 827, in _do_call
    return await self._callback(self.binding, interaction, **params)  # type: ignore
           ^^^^^^^^^^^^^^^^^^^^^^^^^^^^^^^^^^^^^^^^^^^^^^^^^^^^^^^^^
  File "C:\Users\정진혁\OneDrive - Ars Praxia\Documents\GitHub\arislena-reborn\cogs\user_management.py", line 63, in setting
    user_setting = main_db.fetch("user_setting", f"user_ID = {user.ID}")
                   ^^^^^^^^^^^^^^^^^^^^^^^^^^^^^^^^^^^^^^^^^^^^^^^^^^^^^
  File "C:\Users\정진혁\OneDrive - Ars Praxia\Documents\GitHub\arislena-reborn\py_system\database.py", line 35, in fetch
    self.cursor.execute(sql)
sqlite3.OperationalError: no such column: user_ID

The above exception was the direct cause of the following exception:

Traceback (most recent call last):
  File "C:\Users\정진혁\AppData\Roaming\Python\Python311\site-packages\discord\app_commands\tree.py", line 1248, in _call
    await command._invoke_with_namespace(interaction, namespace)
  File "C:\Users\정진혁\AppData\Roaming\Python\Python311\site-packages\discord\app_commands\commands.py", line 853, in _invoke_with_namespace
    return await self._do_call(interaction, transformed_values)
           ^^^^^^^^^^^^^^^^^^^^^^^^^^^^^^^^^^^^^^^^^^^^^^^^^^^^
  File "C:\Users\정진혁\AppData\Roaming\Python\Python311\site-packages\discord\app_commands\commands.py", line 846, in _do_call
    raise CommandInvokeError(self, e) from e
discord.app_commands.errors.CommandInvokeError: Command '설정' raised an exception: OperationalError: no such column: user_ID

2024-01-19 18:57:47 : Command '등록' raised an exception: TypeError: User.__init__() got an unexpected keyword argument 'discord_id'
Traceback (most recent call last):
  File "C:\Users\ghftr\AppData\Roaming\Python\Python311\site-packages\discord\app_commands\commands.py", line 827, in _do_call
    return await self._callback(self.binding, interaction, **params)  # type: ignore
           ^^^^^^^^^^^^^^^^^^^^^^^^^^^^^^^^^^^^^^^^^^^^^^^^^^^^^^^^^
  File "C:\Users\ghftr\Documents\GitHub\arislena-reborn\cogs\user_management.py", line 28, in register
    user = tableobj.User(
           ^^^^^^^^^^^^^^
TypeError: User.__init__() got an unexpected keyword argument 'discord_id'

The above exception was the direct cause of the following exception:

Traceback (most recent call last):
  File "C:\Users\ghftr\AppData\Roaming\Python\Python311\site-packages\discord\app_commands\tree.py", line 1248, in _call
    await command._invoke_with_namespace(interaction, namespace)
  File "C:\Users\ghftr\AppData\Roaming\Python\Python311\site-packages\discord\app_commands\commands.py", line 853, in _invoke_with_namespace
    return await self._do_call(interaction, transformed_values)
           ^^^^^^^^^^^^^^^^^^^^^^^^^^^^^^^^^^^^^^^^^^^^^^^^^^^^
  File "C:\Users\ghftr\AppData\Roaming\Python\Python311\site-packages\discord\app_commands\commands.py", line 842, in _do_call
    raise CommandInvokeError(self, e) from e
discord.app_commands.errors.CommandInvokeError: Command '등록' raised an exception: TypeError: User.__init__() got an unexpected keyword argument 'discord_id'

2024-01-19 19:11:16 : Command '등록' raised an exception: AttributeError: 'User' object has no attribute 'discord_id'
Traceback (most recent call last):
  File "C:\Users\ghftr\AppData\Roaming\Python\Python311\site-packages\discord\app_commands\commands.py", line 827, in _do_call
    return await self._callback(self.binding, interaction, **params)  # type: ignore
           ^^^^^^^^^^^^^^^^^^^^^^^^^^^^^^^^^^^^^^^^^^^^^^^^^^^^^^^^^
  File "C:\Users\ghftr\Documents\GitHub\arislena-reborn\cogs\user_management.py", line 51, in register
    await interaction.response.send_message(embed=embed.register(user), ephemeral=True)
                                                  ^^^^^^^^^^^^^^^^^^^^
  File "C:\Users\ghftr\Documents\GitHub\arislena-reborn\py_discord\embed.py", line 11, in register
    embed.add_field(name="디스코드 아이디", value=user.discord_id)
                                           ^^^^^^^^^^^^^^^
AttributeError: 'User' object has no attribute 'discord_id'

The above exception was the direct cause of the following exception:

Traceback (most recent call last):
  File "C:\Users\ghftr\AppData\Roaming\Python\Python311\site-packages\discord\app_commands\tree.py", line 1248, in _call
    await command._invoke_with_namespace(interaction, namespace)
  File "C:\Users\ghftr\AppData\Roaming\Python\Python311\site-packages\discord\app_commands\commands.py", line 853, in _invoke_with_namespace
    return await self._do_call(interaction, transformed_values)
           ^^^^^^^^^^^^^^^^^^^^^^^^^^^^^^^^^^^^^^^^^^^^^^^^^^^^
  File "C:\Users\ghftr\AppData\Roaming\Python\Python311\site-packages\discord\app_commands\commands.py", line 846, in _do_call
    raise CommandInvokeError(self, e) from e
discord.app_commands.errors.CommandInvokeError: Command '등록' raised an exception: AttributeError: 'User' object has no attribute 'discord_id'

